Let's address these debugging and exception handling scenarios in C\#.

### Question 1: You are debugging an application where an `InvalidOperationException` is being thrown. You suspect the issue might be due to a specific sequence of operations, but the default stack trace doesn't provide enough context. How could you augment your exception handling to include more diagnostic information when this specific exception occurs?

**My Answer:**

When a `InvalidOperationException` occurs, it typically means an object is in an inappropriate state for the requested operation. To augment the diagnostic information beyond the default stack trace, you can catch the specific `InvalidOperationException` and then either:

1.  **Create a New Custom Exception with More Context:** This is the most robust approach. You design a custom exception to carry additional, domain-specific data that helps pinpoint the exact state that led to the invalid operation. You then include the original `InvalidOperationException` as an `InnerException` to preserve the original stack trace.
2.  **Rethrow the Original Exception with an `InnerException` (if applicable) or add context to a general `Exception`:** While `throw;` preserves the stack trace, if you want to add new, specific context to the *same* exception type, you'd typically need a custom one. However, if you're wrapping it in a *different* type of exception (e.g., a more general `ApplicationException` or a custom one if you don't want to define a new type), you can pass the `InvalidOperationException` as the `InnerException`.

Let's demonstrate the first, preferred approach (creating a custom exception) as it provides the most clarity and extensibility.

**C\# Code Example (Augmenting with Custom Exception):**

First, define a custom exception that can hold relevant diagnostic data:

```csharp
using System;

// Custom exception to carry more context for InvalidOperationException
public class StateMismatchException : InvalidOperationException // Deriving from InvalidOperationException for semantic meaning
{
    public string CurrentState { get; }
    public string OperationAttempted { get; }
    public string ExpectedState { get; } // Optional: to indicate what state was expected

    // Standard constructor for message and inner exception
    public StateMismatchException(string message, Exception innerException, string currentState, string operationAttempted, string expectedState = null)
        : base(message, innerException)
    {
        CurrentState = currentState;
        OperationAttempted = operationAttempted;
        ExpectedState = expectedState;
    }

    // Constructor specifically for InvalidOperationException wrapping
    public StateMismatchException(InvalidOperationException innerException, string currentState, string operationAttempted, string expectedState = null)
        : this("Operation attempted in an invalid state.", innerException, currentState, operationAttempted, expectedState) { }

    // Minimal constructor if needed
    public StateMismatchException(string currentState, string operationAttempted)
        : base($"Operation '{operationAttempted}' attempted in state '{currentState}'.")
    {
        CurrentState = currentState;
        OperationAttempted = operationAttempted;
    }
}

public class DeviceController
{
    public enum DeviceState { Initialized, Running, Stopped, Error }

    private DeviceState _currentState = DeviceState.Initialized;
    private int _operationCount = 0;

    public DeviceState GetCurrentState() => _currentState;

    public void Start()
    {
        if (_currentState == DeviceState.Running)
        {
            // Simulate InvalidOperationException for illustration
            throw new InvalidOperationException("Device is already running.");
        }
        Console.WriteLine("Device starting...");
        _currentState = DeviceState.Running;
        _operationCount = 0;
        Console.WriteLine($"Device state: {_currentState}");
    }

    public void PerformOperation()
    {
        if (_currentState != DeviceState.Running)
        {
            // This is the problematic spot: an InvalidOperationException is thrown here.
            // We'll wrap this specific one for better diagnostics.
            try
            {
                throw new InvalidOperationException("Cannot perform operation: Device is not in Running state.");
            }
            catch (InvalidOperationException ex)
            {
                // Catch the specific InvalidOperationException
                // Augment by throwing a custom exception with current state context
                throw new StateMismatchException(
                    innerException: ex, // Preserve the original exception and its stack trace
                    currentState: _currentState.ToString(),
                    operationAttempted: "PerformOperation",
                    expectedState: DeviceState.Running.ToString()
                );
            }
        }
        _operationCount++;
        Console.WriteLine($"Operation {_operationCount} performed.");
    }

    public void Stop()
    {
        if (_currentState == DeviceState.Stopped)
        {
            throw new InvalidOperationException("Device is already stopped.");
        }
        Console.WriteLine("Device stopping...");
        _currentState = DeviceState.Stopped;
        Console.WriteLine($"Device state: {_currentState}");
    }
}

public class Program
{
    public static void Main(string[] args)
    {
        DeviceController controller = new DeviceController();

        // Scenario 1: Correct flow
        Console.WriteLine("--- Scenario 1: Correct Flow ---");
        controller.Start();
        controller.PerformOperation();
        controller.Stop();

        // Scenario 2: Invalid operation where we add more context
        Console.WriteLine("\n--- Scenario 2: Invalid Operation (Augmented) ---");
        controller = new DeviceController(); // Reset controller to Initialized state
        Console.WriteLine($"Initial state for scenario 2: {controller.GetCurrentState()}");

        try
        {
            controller.PerformOperation(); // This will now throw our custom exception
        }
        catch (StateMismatchException customEx)
        {
            Console.WriteLine("\nCaught Augmented Exception:");
            Console.WriteLine($"Custom Message: {customEx.Message}");
            Console.WriteLine($"Current Device State: {customEx.CurrentState}");
            Console.WriteLine($"Operation Attempted: {customEx.OperationAttempted}");
            Console.WriteLine($"Expected Device State: {customEx.ExpectedState}");
            Console.WriteLine("\nOriginal Exception Details (InnerException):");
            Console.WriteLine($"  Type: {customEx.InnerException?.GetType().Name}");
            Console.WriteLine($"  Message: {customEx.InnerException?.Message}");
            Console.WriteLine($"  Original Stack Trace: \n{customEx.InnerException?.StackTrace}"); // Show original
            Console.WriteLine($"\nNew Stack Trace (from custom exception throw): \n{customEx.StackTrace}"); // Show new
        }
        catch (Exception ex)
        {
            Console.WriteLine($"Caught a generic exception: {ex.Message}");
        }
    }
}
```

**Explanation of Augmentation:**

1.  **Custom Exception (`StateMismatchException`):**

      * We created `StateMismatchException` which derives from `InvalidOperationException` (or could derive directly from `Exception` if it's a more general state error).
      * It has custom properties: `CurrentState`, `OperationAttempted`, and `ExpectedState`. These properties capture the specific pieces of information critical for understanding *why* the `InvalidOperationException` occurred in this particular context.
      * A key constructor takes the original `InvalidOperationException` as an `innerException`. This is paramount because it preserves the **original stack trace** of the `InvalidOperationException`, allowing you to see exactly where the initial invalid state check failed.

2.  **`try-catch` and Rethrowing Custom Exception:**

      * Inside `DeviceController.PerformOperation()`, where the `InvalidOperationException` is thrown, we wrap it in a `try-catch` block.
      * We explicitly `catch (InvalidOperationException ex)`.
      * Instead of just rethrowing `ex` (which would just give us the original stack trace without the context), we **throw a new `StateMismatchException`**, passing `ex` as its `innerException` and providing the values of the `_currentState`, `operationAttempted`, and `expectedState`.

**Benefits of this approach:**

  * **Rich Context:** The custom exception carries specific, relevant data about the application's state at the moment of failure, which is impossible with generic exceptions.
  * **Original Stack Trace Preserved:** By using `InnerException`, you don't lose the critical information about where the `InvalidOperationException` was originally thrown. You get both the original context and the added diagnostic data.
  * **Semantic Clarity:** The type `StateMismatchException` immediately tells you *what kind* of `InvalidOperationException` occurred within your domain, allowing for more specific `catch` logic higher up.
  * **Improved Logging:** When you log this exception, all the custom properties are available, providing a much richer diagnostic footprint.

This method transforms a generic `InvalidOperationException` into a highly informative diagnostic tool tailored to your application's logic.

-----

### Question 2: Consider a scenario where you have nested method calls, and an exception occurs deep down in the call stack. Explain how exceptions propagate up the call stack and how `catch` blocks intercept them.

**My Answer:**

When an exception occurs deep within a series of nested method calls, it doesn't just stop the program at that point. Instead, it "propagates" or "bubbles up" the call stack until it finds a suitable `catch` block or, if no such block is found, it reaches the very top of the application, leading to termination. This process is often referred to as **stack unwinding**.

Let's illustrate with a scenario:

```csharp
using System;

public class CallStackDemonstrator
{
    // Method 1: Top of the call stack
    public void StartApplicationProcess()
    {
        Console.WriteLine("1. StartApplicationProcess: Starting application...");
        try
        {
            ProcessUserData(); // Calls Method 2
        }
        catch (FormatException ex) // This catch block can handle FormatException
        {
            Console.WriteLine($"1. StartApplicationProcess: Caught FormatException: {ex.Message}");
            Console.WriteLine("    Application process completed with a specific error.");
        }
        catch (Exception ex) // This catch block can handle any other exception
        {
            Console.WriteLine($"1. StartApplicationProcess: Caught general exception: {ex.Message}");
            Console.WriteLine("    Application process completed with an unexpected error.");
        }
        finally
        {
            Console.WriteLine("1. StartApplicationProcess: Cleanup after process attempt.");
        }
        Console.WriteLine("1. StartApplicationProcess: Exiting.");
    }

    // Method 2: Middle of the call stack
    private void ProcessUserData()
    {
        Console.WriteLine("2. ProcessUserData: Processing user data...");
        // No try-catch block here, so if an exception occurs in ValidateAndParse,
        // it will propagate up to StartApplicationProcess.
        ValidateAndParseInput("InvalidNumber"); // Calls Method 3 (will throw)
        Console.WriteLine("2. ProcessUserData: Data processed successfully."); // This line won't be reached
    }

    // Method 3: Deepest in the call stack, where the exception originates
    private int ValidateAndParseInput(string input)
    {
        Console.WriteLine($"3. ValidateAndParseInput: Validating and parsing input '{input}'...");
        try
        {
            int number = int.Parse(input); // This line will throw a FormatException
            Console.WriteLine($"3. ValidateAndParseInput: Parsed number: {number}"); // This line won't be reached
            return number;
        }
        catch (OverflowException ex) // This specific catch
        {
            Console.WriteLine($"3. ValidateAndParseInput: Caught OverflowException (this won't happen here): {ex.Message}");
            // If it caught, it would be handled here. Since it's FormatException, it's skipped.
            throw; // Rethrowing if it were caught
        }
        finally
        {
            Console.WriteLine("3. ValidateAndParseInput: Finished validation/parsing attempt.");
        }
        // No catch for FormatException in this method
    }

    public static void Main(string[] args)
    {
        CallStackDemonstrator app = new CallStackDemonstrator();
        app.StartApplicationProcess();
    }
}
```

**How Exceptions Propagate and are Intercepted:**

1.  **Exception Originates (`ValidateAndParseInput`):**

      * The `Main` method calls `StartApplicationProcess`.
      * `StartApplicationProcess` calls `ProcessUserData`.
      * `ProcessUserData` calls `ValidateAndParseInput("InvalidNumber")`.
      * Inside `ValidateAndParseInput`, the line `int number = int.Parse(input);` attempts to convert "InvalidNumber" to an integer. This operation is invalid, so a `System.FormatException` is immediately **thrown**.

2.  **Stack Unwinding Begins (From `ValidateAndParseInput`):**

      * As soon as `FormatException` is thrown, the normal execution of `ValidateAndParseInput` is suspended.
      * The CLR looks for a `try-catch` block within `ValidateAndParseInput` that can handle `FormatException`.
      * In our example, `ValidateAndParseInput` has a `try-catch` block, but it only catches `OverflowException`. It does *not* have a `catch` block for `FormatException`.
      * Because no suitable `catch` block is found in `ValidateAndParseInput`, the CLR executes the `finally` block of `ValidateAndParseInput` (if present).
      * After the `finally` block, the exception is automatically **propagated up** to the **calling method** (the method that called `ValidateAndParseInput`), which is `ProcessUserData`. The stack frame for `ValidateAndParseInput` is "unwound" or removed from the call stack.

3.  **Propagation to Caller (`ProcessUserData`):**

      * The `FormatException` now appears as if it was thrown directly from the line `ValidateAndParseInput("InvalidNumber");` within `ProcessUserData`.
      * The CLR looks for a `try-catch` block within `ProcessUserData` to handle the `FormatException`.
      * In our example, `ProcessUserData` does *not* have a `try-catch` block at all.
      * Since no handler is found, the exception is again automatically **propagated up** to the **calling method** (the method that called `ProcessUserData`), which is `StartApplicationProcess`. The stack frame for `ProcessUserData` is unwound.

4.  **Interception by `catch` Block (`StartApplicationProcess`):**

      * The `FormatException` now appears as if it was thrown directly from the line `ProcessUserData();` within `StartApplicationProcess`.
      * The CLR looks for a `try-catch` block within `StartApplicationProcess` to handle `FormatException`.
      * `StartApplicationProcess` *does* have a `try-catch` block with a `catch (FormatException ex)` specifically for this type.
      * The CLR finds this match. The code inside this specific `catch` block is executed. The exception is now considered **handled**.

5.  **Execution Continues After `try-catch` (`StartApplicationProcess`):**

      * Once the `catch` block in `StartApplicationProcess` finishes executing, the `finally` block associated with that `try-catch` is executed.
      * After the `finally` block, the program's execution flow resumes normally from the point immediately following the entire `try-catch-finally` construct within `StartApplicationProcess`. The application continues running.

**Summary of Unwinding:**

  * When an exception is thrown, the CLR stops execution at that point.
  * It immediately executes any `finally` blocks in the current method's `try-catch-finally` construct.
  * It then checks if there's a matching `catch` block in the current method.
  * If found, the `catch` block executes, and execution continues *after* the `try-catch-finally`.
  * If not found, the current method's stack frame is "unwound" (removed), and the exception is rethrown to the calling method.
  * This process repeats up the call stack until a matching `catch` block is found or the application's main thread (or the thread where the exception originated) is reached.
  * If the exception reaches the top of the call stack of the application's main thread without being handled, the application will terminate (unless a global exception handler is in place).

-----

### Question 3: When might you choose to return an error code or use a result object (e.g., `Result<T>`) instead of throwing an exception? What are the pros and cons of this approach compared to exceptions?

**My Answer:**

You might choose to return an error code or a result object instead of throwing an exception when dealing with **expected failure conditions** that are considered part of the "normal" operational logic or business flow, rather than truly "exceptional" or unexpected errors.

**When to Use Error Codes / Result Objects:**

1.  **Expected Validation Failures:** When a method receives user input or parameters, and it's highly probable or expected that the input might be invalid.
      * *Example:* A `Login` method might return `LoginResult.Success`, `LoginResult.InvalidCredentials`, `LoginResult.UserNotFound`.
      * *Example:* A `ParseNumber` method might return `Result<int>` where `Result.IsSuccess` is false if the string cannot be parsed.
2.  **Common Business Rule Violations:** When a business operation might fail due to a business rule (e.g., insufficient stock, account frozen, duplicate entry). These are anticipated outcomes.
      * *Example:* An `AddToCart` method might return `AddResult.Success` or `AddResult.OutOfStock`.
3.  **Known Non-Exceptional Conditions:** For situations where a function's primary purpose is to *check* for a condition, and the "failure" simply means the condition wasn't met.
      * *Example:* `File.Exists()` returns `bool`, not throws if the file isn't found. `Dictionary<TKey, TValue>.TryGetValue()` returns `bool` and an `out` parameter.

**Pros of Error Codes / Result Objects vs. Exceptions:**

1.  **Performance:** Throwing and catching exceptions is computationally expensive due to stack unwinding and object creation. For frequent, expected "failures," returning an error code or a result object is significantly faster.
2.  **Clear Control Flow:** Using return values makes the control flow explicit and easy to follow. You use standard `if-else` or `switch` statements to handle different outcomes, which is intuitive and directly visible in the code.
3.  **Encourages Explicit Handling:** Callers are forced to check the return value. It's difficult to "swallow" an error when it's part of the method's explicit return signature, unlike exceptions which can be accidentally ignored.
4.  **Type Safety (with Result Objects):** Generic result objects (e.g., `Result<TSuccess, TError>`) can enforce type safety for both success and error outcomes, making it clear what type of error information is returned.

**Cons of Error Codes / Result Objects vs. Exceptions:**

1.  **Can Be Ignored (Error Codes):** While result objects make it harder, a simple integer error code can easily be ignored by the caller, leading to silent failures if not checked.
2.  **Less Rich Context (Simple Error Codes):** Basic error codes often don't provide as much rich contextual information (like stack traces or `InnerException`s) as exceptions do. A `Result` object can mitigate this by having properties for messages, error types, etc.
3.  **Verbose `if-else` Chains:** Extensive use of error codes can lead to deep, nested `if-else` or `switch` statements, making the code harder to read and potentially violating the single responsibility principle if the method ends up handling too many failure conditions.
4.  **No Stack Trace:** Since no exception is thrown, there's no automatic stack trace information, which can sometimes make debugging unexpected errors (even if they were "expected" failures) harder.
5.  **Breaks the Normal Flow:** For truly exceptional conditions that prevent the method from completing its intended operation, an exception is a much clearer signal that something went fundamentally wrong and requires immediate attention. Mixing expected failures with true exceptions can blur the lines.

**Conclusion:**

The general guideline is:

  * **Use Exceptions for Exceptional (Unexpected) Conditions:** Situations that prevent a method from completing its intended purpose due to an unforeseen problem (e.g., file not found, network down, database error, out of memory, programming bugs like null reference).
  * **Use Error Codes or Result Objects for Expected (Anticipated) Failure Conditions:** Situations where a method might not succeed, but this outcome is part of its defined behavior and can be handled as a regular branch in the logic (e.g., validation errors, business rule violations, "item not found" in a search).

A `Result<T>` or `Either<TSuccess, TFailure>` pattern is a powerful way to get the benefits of explicit error handling without the performance cost and control flow disruption of exceptions for routine failures.

-----

### Question 4: You're working on a library method that performs a critical operation. If the operation fails, you want to log the error but still rethrow the exception so that calling code can handle it further up the stack. Demonstrate the correct way to do this.

**My Answer:**

When you want to log an exception at a lower level (e.g., within a library method) but still allow it to propagate up to higher levels of the application for further handling, it's crucial to **rethrow the exception correctly to preserve its original stack trace**. The correct way to do this is by using `throw;` (without the exception variable).

**C\# Code Example:**

```csharp
using System;
using System.IO;

// Assume this is part of your library code
public class CriticalOperationLibrary
{
    // A simplified logger for demonstration purposes
    private static void LogError(Exception ex, string message)
    {
        Console.ForegroundColor = ConsoleColor.Red;
        Console.WriteLine($"[LIBRARY LOG ERROR]: {message}");
        Console.WriteLine($"[LIBRARY LOG DETAILS]: Exception Type: {ex.GetType().Name}");
        Console.WriteLine($"[LIBRARY LOG DETAILS]: Message: {ex.Message}");
        Console.WriteLine($"[LIBRARY LOG DETAILS]: Stack Trace:\n{ex.StackTrace}");
        Console.ResetColor();
    }

    public static void PerformCriticalFileOperation(string filePath, string data)
    {
        Console.WriteLine($"\nLibrary: Attempting critical file operation on '{filePath}'...");
        try
        {
            // Simulate a critical operation that might fail
            if (!File.Exists(filePath))
            {
                // This will throw a FileNotFoundException
                throw new FileNotFoundException("The specified file was not found for critical operation.", filePath);
            }

            // Simulate some operation that might cause other IO errors
            File.AppendAllText(filePath, data);
            Console.WriteLine($"Library: Data successfully written to '{filePath}'.");
        }
        catch (FileNotFoundException ex)
        {
            // 1. Log the specific error at the library level
            LogError(ex, $"Critical file operation failed: File not found.");

            // 2. Rethrow the original exception to propagate it up the stack.
            //    'throw;' PRESERVES the original stack trace.
            throw;
        }
        catch (IOException ex) // Catch other general IO errors
        {
            // 1. Log the specific error at the library level
            LogError(ex, $"Critical file operation failed: An I/O error occurred.");

            // 2. Rethrow the original exception.
            throw;
        }
        catch (Exception ex) // Catch any other unexpected exceptions
        {
            // 1. Log the general error
            LogError(ex, $"An unexpected error occurred during critical file operation.");

            // 2. Rethrow the original exception.
            throw;
        }
    }
}

// Assume this is your application code that uses the library
public class Application
{
    public static void Main(string[] args)
    {
        string existingFilePath = "mydata.txt";
        string nonExistentFilePath = "missing_file.txt";

        // Create a dummy file for testing success case
        File.WriteAllText(existingFilePath, "Initial data.\n");

        // Scenario 1: Successful operation
        try
        {
            CriticalOperationLibrary.PerformCriticalFileOperation(existingFilePath, "App Data 1.\n");
            Console.WriteLine("Application: Critical operation completed successfully.");
        }
        catch (Exception appEx)
        {
            Console.WriteLine($"Application: Caught an unexpected error from library: {appEx.Message}");
        }

        // Scenario 2: Operation fails (file not found)
        try
        {
            CriticalOperationLibrary.PerformCriticalFileOperation(nonExistentFilePath, "App Data 2.\n");
            Console.WriteLine("Application: Critical operation completed successfully (should not happen here).");
        }
        catch (FileNotFoundException appEx) // Application catches the specific exception
        {
            Console.ForegroundColor = ConsoleColor.Yellow;
            Console.WriteLine($"\nApplication: Successfully handled FileNotFoundException for '{appEx.FileName}'!");
            Console.WriteLine($"Application: Error Message: {appEx.Message}");
            Console.WriteLine($"Application: Full Stack Trace: \n{appEx.StackTrace}"); // Stack trace includes original origin
            Console.ResetColor();
        }
        catch (Exception appEx)
        {
            Console.WriteLine($"\nApplication: Caught a generic error: {appEx.Message}");
            Console.WriteLine($"Application: Full Stack Trace: \n{appEx.StackTrace}");
        }

        // Clean up
        File.Delete(existingFilePath);
    }
}
```

**Explanation:**

1.  **`CriticalOperationLibrary.PerformCriticalFileOperation` Method:**

      * This method contains the `try` block around the critical file operations.
      * It has multiple `catch` blocks for specific `IOException` types (`FileNotFoundException`, `IOException`) and a general `Exception` catch-all.
      * Inside each `catch` block:
          * `LogError(ex, "...");` is called. This simulates logging the full details of the exception (type, message, and crucially, the stack trace) at the point where it was first caught in the library. This ensures that you have a record of the error even if it's handled or ignored higher up the stack.
          * `throw;` is used to rethrow the exception. This is the **correct way** because it **preserves the original stack trace**. The stack trace will show the full call sequence from `Main` -\> `PerformCriticalFileOperation` -\> the line where the `FileNotFoundException` was originally thrown. If `throw ex;` were used, the stack trace would be truncated, making it harder to debug the original cause.

2.  **`Application.Main` Method:**

      * This method calls the library method `PerformCriticalFileOperation`.
      * It wraps the library call in its own `try-catch` block, demonstrating how the higher-level application code can then catch the same exception that was rethrown by the library.
      * When `FileNotFoundException` is caught in `Main`, `appEx.StackTrace` will contain the complete call stack from the original throw point within `PerformCriticalFileOperation` all the way back up to `Main`.

This pattern allows you to:

  * **Log diagnostic information** at the point of failure (e.g., within a specific library or component) for immediate insight.
  * **Propagate the error** so that higher-level components or the application's global exception handler can react to it, potentially providing user feedback, performing recovery, or triggering alerts.
  * **Preserve the full context** of the error through the stack trace, which is invaluable for debugging.