Let's analyze these scenarios to determine the most appropriate error handling strategy, focusing on the principles of "exceptions for exceptional conditions" and maintaining clear, efficient code.

-----

### 1\. Youâ€™re building a file processing tool. The file may or may not exist. Do you check with `File.Exists()` or just try opening it in a `try-catch`? Why?

You should generally **check with `File.Exists()` first**, and only use `try-catch` for unexpected or genuinely exceptional issues during the *attempted opening or reading* of the file.

**Why `File.Exists()` first is preferred:**

1.  **Expected Condition:** In a file processing tool, a file *not* existing is often an expected, common, and recoverable scenario (e.g., user mistyped a filename, a previous process failed to create it). Exceptions should be reserved for *exceptional* events that disrupt normal flow.
2.  **Performance:** Throwing and catching exceptions has a significant performance overhead. For a condition that might occur frequently, relying on exceptions becomes a performance bottleneck. `File.Exists()` is a lightweight check.
3.  **Readability and Intent:** The `if (File.Exists())` block clearly communicates the intent: "If the file is there, do X; otherwise, do Y." Using `try-catch` to handle a missing file can obscure the primary logic and implies that a missing file is an "error" rather than a possible state.
4.  **Specific Error Handling:** `File.Exists()` allows you to provide a specific, user-friendly message for the "file not found" case, distinct from other potential file errors (e.g., permission denied, file in use).

**When `try-catch` is still necessary (after `File.Exists()`):**

Even after checking `File.Exists()`, you should still wrap the actual file I/O operations (like `File.OpenRead`, `StreamReader.ReadLine`) in a `try-catch` block. This is because between the `File.Exists()` check and the actual opening of the file, other **exceptional conditions** can arise that `File.Exists()` doesn't cover:

  * **Race Conditions:** Another process might delete the file *after* `File.Exists()` returns true, but *before* your code opens it.
  * **Permission Denied:** Your application might not have the necessary permissions to read the file.
  * **File In Use:** Another application might have an exclusive lock on the file.
  * **Disk Errors:** Hardware failures can occur during read/write.
  * **Path Too Long:** The file path might exceed system limits.

These are truly *exceptional* conditions that `try-catch` is designed to handle gracefully, allowing you to log them, alert the user to a more severe problem, or attempt recovery.

**Code Example:**

```csharp
using System;
using System.IO;

public class FileProcessingExample
{
    public static void ProcessFile(string filePath)
    {
        Console.WriteLine($"\n--- Attempting to process file: {filePath} ---");

        if (!File.Exists(filePath)) // Preferred: Check for expected condition
        {
            Console.WriteLine($"Error: File '{filePath}' does not exist. Please provide a valid path.");
            // Log this as a warning or user error, do not throw.
            return; // Exit gracefully
        }

        try
        {
            // Now that we know it exists, try to open and read.
            // Wrap in try-catch for truly *exceptional* I/O errors.
            using (StreamReader reader = new StreamReader(filePath))
            {
                string? line;
                int lineNumber = 0;
                while ((line = reader.ReadLine()) != null)
                {
                    lineNumber++;
                    Console.WriteLine($"  Line {lineNumber}: {line}");
                    // Process the line...
                }
                Console.WriteLine($"Successfully processed {lineNumber} lines from '{filePath}'.");
            }
        }
        catch (UnauthorizedAccessException ex)
        {
            Console.WriteLine($"Error: Access to '{filePath}' denied. {ex.Message}");
            // Log as a security/permission issue.
        }
        catch (IOException ex) // Catches more general I/O errors like file in use, disk errors
        {
            Console.WriteLine($"Error: An I/O error occurred while accessing '{filePath}'. {ex.Message}");
            // Log as a system error.
        }
        catch (Exception ex) // General fallback for unexpected errors
        {
            Console.WriteLine($"Error: An unexpected error occurred while processing '{filePath}'. {ex.Message}");
            // Log full exception details.
        }
    }

    public static void Main(string[] args)
    {
        string existingFile = "test_data.txt";
        File.WriteAllText(existingFile, "Hello, world!\nThis is a test file.");

        ProcessFile(existingFile);
        ProcessFile("non_existent_file.txt");

        // Simulate a permission denied scenario (manual intervention needed to fully test)
        // Try to create a file in a protected directory or remove read permissions manually for a file.
        // ProcessFile("/path/to/protected/file.txt");

        File.Delete(existingFile); // Clean up
    }
}
```

**Conclusion:** Use `File.Exists()` for the expected "file not found" condition, and use `try-catch` around the actual file operations for the unexpected, system-level I/O exceptions.

-----

### 2\. In a payment API, should you throw an exception if a transaction fails due to insufficient funds, or return a result code?

In a payment API, if a transaction fails due to **insufficient funds**, you should **return a result code (or a structured response object) instead of throwing an exception.**

**Why a Result Code/Structured Response is Preferred:**

1.  **Expected Condition:** Insufficient funds is a common, anticipated outcome in a payment system. It's a business rule violation, not an unrecoverable system error. Customers frequently attempt transactions without enough money.

2.  **Performance:** As discussed, throwing exceptions is costly. For a condition that might occur regularly (especially in high-volume systems), using exceptions would degrade performance significantly.

3.  **Clear API Contract:** An API that returns a result object (e.g., `PaymentResult` with `Status` and `ErrorCode`) clearly communicates that a transaction can fail in various defined ways, and the client is expected to handle those specific failures.

4.  **Readability and Maintainability:** The client code becomes much cleaner. Instead of wrapping every payment call in a `try-catch` block just to handle `InsufficientFundsException`, it can simply check a property of the returned result:

    ```csharp
    // With Result Object
    PaymentResult result = paymentService.ProcessPayment(amount, accountId);
    if (result.Status == PaymentStatus.Success) { /* ... */ }
    else if (result.Status == PaymentStatus.InsufficientFunds) { /* ... */ }
    else if (result.Status == PaymentStatus.FraudDetected) { /* ... */ }
    else { /* Handle other errors */ }

    // With Exceptions (less ideal)
    try
    {
        paymentService.ProcessPayment(amount, accountId);
    }
    catch (InsufficientFundsException) { /* ... */ }
    catch (FraudDetectedException) { /* ... */ }
    catch (NetworkErrorException) { /* ... */ } // Still need this for true exceptions
    ```

5.  **Granularity:** A structured result object allows for much more granular information about the failure (e.g., `ErrorCode`, `ErrorMessage`, `AvailableFunds`, `RequiredFunds`) without needing to create a new exception type for every possible business validation failure.

**When to still throw an exception in a Payment API:**

Exceptions should be reserved for truly *exceptional* circumstances that indicate a system problem or an unrecoverable state, not a business rule violation:

  * **API Misuse:** Invalid API keys, malformed request bodies that don't pass schema validation.
  * **System Errors:** Database connection failures, network outages to the payment gateway, internal server errors, unhandled internal bugs.
  * **Security Breaches:** Detection of tampering or unauthorized access attempts.

**Code Example:**

```csharp
using System;

public enum PaymentStatus
{
    Success,
    InsufficientFunds,
    InvalidPaymentMethod,
    FraudDetected,
    GatewayError, // A non-recoverable system error, but still a status
    UnknownError
}

public class PaymentResult
{
    public PaymentStatus Status { get; set; }
    public string Message { get; set; } = string.Empty;
    public decimal AmountProcessed { get; set; }
    public string TransactionId { get; set; } = string.Empty;

    // Optional: for detailed errors
    public Exception? ExceptionDetail { get; set; } // If a true underlying exception occurred
}

public class PaymentService
{
    public PaymentResult ProcessPayment(decimal amount, string accountNumber)
    {
        Console.WriteLine($"\n--- Attempting to process payment of {amount:C} for account {accountNumber} ---");

        if (string.IsNullOrEmpty(accountNumber) || accountNumber.Length < 5)
        {
            return new PaymentResult { Status = PaymentStatus.InvalidPaymentMethod, Message = "Invalid account number format." };
        }

        // Simulate business logic
        decimal accountBalance = GetAccountBalance(accountNumber);
        if (amount > accountBalance)
        {
            return new PaymentResult { Status = PaymentStatus.InsufficientFunds, Message = $"Account has insufficient funds. Balance: {accountBalance:C}." };
        }

        // Simulate external gateway call that might fail unexpectedly (a true exception)
        try
        {
            SimulateGatewayTransaction(amount); // This might throw a NetworkException or similar
            string transactionId = Guid.NewGuid().ToString();
            Console.WriteLine($"Payment successful! Transaction ID: {transactionId}");
            return new PaymentResult { Status = PaymentStatus.Success, Message: "Payment processed successfully.", AmountProcessed = amount, TransactionId = transactionId };
        }
        catch (TimeoutException ex) // Example of a true system-level exception
        {
            Console.WriteLine($"Gateway timeout: {ex.Message}");
            return new PaymentResult { Status = PaymentStatus.GatewayError, Message = "Payment gateway timed out.", ExceptionDetail = ex };
        }
        catch (Exception ex)
        {
            Console.WriteLine($"An unexpected error occurred during gateway call: {ex.Message}");
            return new PaymentResult { Status = PaymentStatus.UnknownError, Message = "An unexpected error occurred during payment.", ExceptionDetail = ex };
        }
    }

    private decimal GetAccountBalance(string accountNumber)
    {
        // Simulate database lookup
        return accountNumber == "12345" ? 100.00m : 500.00m; // Example balances
    }

    private void SimulateGatewayTransaction(decimal amount)
    {
        // Simulate a scenario where a real exception (e.g., network, service unavailable) occurs
        if (amount > 400 && amount < 450)
        {
            throw new TimeoutException("Payment gateway is unresponsive.");
        }
        Console.WriteLine("  Gateway transaction simulated successfully.");
    }
}

public class PaymentClient
{
    public static void Main(string[] args)
    {
        PaymentService service = new PaymentService();

        // Scenario 1: Success
        PaymentResult result1 = service.ProcessPayment(50.00m, "12345");
        HandlePaymentResult(result1);

        // Scenario 2: Insufficient Funds (expected business rule failure)
        PaymentResult result2 = service.ProcessPayment(150.00m, "12345");
        HandlePaymentResult(result2);

        // Scenario 3: Invalid Input (expected validation failure)
        PaymentResult result3 = service.ProcessPayment(10.00m, "abc");
        HandlePaymentResult(result3);

        // Scenario 4: Gateway Error (simulated system exception)
        PaymentResult result4 = service.ProcessPayment(420.00m, "67890");
        HandlePaymentResult(result4);

        // Scenario 5: Another success
        PaymentResult result5 = service.ProcessPayment(10.00m, "67890");
        HandlePaymentResult(result5);
    }

    private static void HandlePaymentResult(PaymentResult result)
    {
        switch (result.Status)
        {
            case PaymentStatus.Success:
                Console.WriteLine($"SUCCESS: {result.Message} (Txn ID: {result.TransactionId})");
                break;
            case PaymentStatus.InsufficientFunds:
                Console.WriteLine($"FAILURE (Insufficient Funds): {result.Message}");
                // Advise user to add funds
                break;
            case PaymentStatus.InvalidPaymentMethod:
                Console.WriteLine($"FAILURE (Invalid Input): {result.Message}");
                // Prompt user for correct details
                break;
            case PaymentStatus.GatewayError:
                Console.WriteLine($"FAILURE (System Error): {result.Message}");
                // Log exception for ops team, advise user to try again later
                if (result.ExceptionDetail != null)
                {
                    Console.WriteLine($"  Detailed Exception: {result.ExceptionDetail.GetType().Name} - {result.ExceptionDetail.Message}");
                }
                break;
            case PaymentStatus.UnknownError:
                Console.WriteLine($"FAILURE (Unknown Error): {result.Message}");
                // Log extensively, escalate
                break;
            default:
                break;
        }
    }
}
```

-----

### 3\. You find a method using try/catch to check if a database record exists. How would you improve it?

This is a classic anti-pattern. Using `try/catch` to check for record existence is inefficient and semantically incorrect because "record not found" is an **expected condition**, not an exceptional one.

**Original (Bad) Approach:**

```csharp
// Inside a data access layer method, e.g., GetUserById
public User GetUserById(int id)
{
    try
    {
        // This query might throw an exception (e.g., InvalidOperationException if using Single()
        // or a custom DataNotFoundException from your ORM/DAL) if no record is found.
        var user = _dbContext.Users.Single(u => u.Id == id); // Throws if not found
        return user;
    }
    catch (InvalidOperationException) // Catching exception for "not found"
    {
        Console.WriteLine($"User with ID {id} not found.");
        return null; // Or throw a specific UserNotFoundException, which is still not ideal
    }
}

// Calling code
try
{
    var user = GetUserById(123);
    Console.WriteLine(user.Name);
}
catch (Exception) // Catching again in calling code
{
    Console.WriteLine("User not found.");
}
```

**How to Improve It (Preferred Approaches):**

The improvement involves changing the data access method's contract to explicitly handle the "not found" scenario without throwing an exception.

**Option 1: Return Null (Most Common for Reference Types)**

Change the return type to nullable (`User?`) and return `null` if the record isn't found. This is simple and effective.

```csharp
// Inside your data access layer/repository
public class UserRepository
{
    private readonly List<User> _users = new List<User>(); // Simulating DB context

    public UserRepository()
    {
        _users.Add(new User { Id = 1, Name = "Alice" });
        _users.Add(new User { Id = 2, Name = "Bob" });
    }

    public User? GetUserById(int id)
    {
        // Use LINQ's SingleOrDefault() or FirstOrDefault() which return null if no match is found
        // instead of throwing an exception.
        User? user = _users.SingleOrDefault(u => u.Id == id);
        return user;
    }
}

// Calling Code:
public class DatabaseClient
{
    public static void Main(string[] args)
    {
        UserRepository repo = new UserRepository();

        int userId1 = 1;
        User? user1 = repo.GetUserById(userId1);
        if (user1 != null)
        {
            Console.WriteLine($"Found user: {user1.Name}");
        }
        else
        {
            Console.WriteLine($"User with ID {userId1} not found.");
        }

        int userId3 = 3;
        User? user3 = repo.GetUserById(userId3);
        if (user3 != null)
        {
            Console.WriteLine($"Found user: {user3.Name}");
        }
        else
        {
            Console.WriteLine($"User with ID {userId3} not found.");
        }
    }
}
```

**Option 2: `TryGetValue` Pattern (Especially useful for `Dictionary` or custom types)**

While `FirstOrDefault` is good, sometimes an explicit `Try` pattern is clearer or more efficient if you need to know if it existed and possibly get some other info.

```csharp
// In your data access layer/repository
public class UserRepository
{
    private readonly Dictionary<int, User> _userDictionary = new Dictionary<int, User>();

    public UserRepository()
    {
        _userDictionary.Add(1, new User { Id = 1, Name = "Alice" });
        _userDictionary.Add(2, new User { Id = 2, Name = "Bob" });
    }

    public bool TryGetUserById(int id, out User? user)
    {
        // Directly maps to Dictionary's TryGetValue pattern, common in many ORMs too.
        return _userDictionary.TryGetValue(id, out user);
    }
}

// Calling Code:
public class DatabaseClient
{
    public static void Main(string[] args)
    {
        UserRepository repo = new UserRepository();

        int userId1 = 1;
        if (repo.TryGetUserById(userId1, out User? user1))
        {
            Console.WriteLine($"Found user: {user1.Name}");
        }
        else
        {
            Console.WriteLine($"User with ID {userId1} not found.");
        }
    }
}
```

**Why these improvements are better:**

  * **Clarity:** The code explicitly states that the user might not be found, making the logic easier to follow.
  * **Performance:** Avoiding exceptions for expected outcomes significantly reduces overhead.
  * **Correctness:** It uses the language features (nullable types, LINQ methods like `SingleOrDefault`, `FirstOrDefault`, or `TryGetValue` pattern) designed for these scenarios, rather than misusing exception handling.
  * **Separation of Concerns:** The data access layer's responsibility is to retrieve data. If data isn't found, it's a valid outcome, not an "error" that should bubble up as an exception unless it's a deeper system problem (e.g., DB connection down).

-----

### 4\. You have a bulk import process where some items might fail. Should you use exceptions to skip bad records?

**No, you should generally NOT use exceptions to skip bad records in a bulk import process.**

**Why not:**

1.  **Expected Failures:** In a bulk import, it's often *expected* that a certain percentage of records might be malformed, incomplete, or violate business rules. These are anticipated conditions, not exceptional system errors.
2.  **Performance:** Throwing an exception for every bad record would be extremely slow and inefficient. Imagine importing millions of records where 5% are invalid â€“ that's 50,000 exceptions, each incurring a significant performance penalty.
3.  **Code Readability:** Wrapping the inner loop of a bulk import in a `try-catch` and then `continue`ing in the `catch` block makes the code harder to read and debug. It obscures the normal flow of "process item, if valid; otherwise, log error and move on."
4.  **Debugging Difficulty:** Using exceptions for flow control can mask true, unexpected system errors, making it harder to distinguish between a "bad data" issue and a "code bug."

**Recommended Approach: Validate and Collect Errors**

The best practice is to **validate each record explicitly** and **collect all errors** rather than interrupting the flow with exceptions.

**Steps:**

1.  **Iterate through all records.**
2.  **For each record, perform validation checks.**
3.  **If a record is valid:** Process it (e.g., insert into DB, transform).
4.  **If a record is invalid:**
      * **Log the error:** Detail the record ID/content and the specific reason for failure.
      * **Add to an error collection:** Collect all invalid records or their error details.
      * **Continue to the next record.**
5.  **At the end of the batch/process:** Report all errors (e.g., generate a log file of failures, send a summary report).

**Code Example:**

```csharp
using System;
using System.Collections.Generic;
using System.IO;
using System.Linq;

public class ImportRecord
{
    public int Id { get; set; }
    public string? Name { get; set; }
    public int Age { get; set; }
    public string? Email { get; set; }
}

public class ImportError
{
    public int RecordIndex { get; set; }
    public string RawLine { get; set; } = string.Empty;
    public string ErrorMessage { get; set; } = string.Empty;
}

public class BulkImporter
{
    public static void ImportData(IEnumerable<string> rawLines)
    {
        List<ImportRecord> validRecords = new List<ImportRecord>();
        List<ImportError> errors = new List<ImportError>();
        int recordIndex = 0;

        Console.WriteLine("--- Starting Bulk Import Process ---");

        foreach (string line in rawLines)
        {
            recordIndex++;
            try
            {
                // Simulate parsing a CSV line or similar
                string[] parts = line.Split(',');
                if (parts.Length != 4)
                {
                    errors.Add(new ImportError { RecordIndex = recordIndex, RawLine = line, ErrorMessage = "Incorrect number of fields." });
                    continue; // Skip to next record without throwing
                }

                if (!int.TryParse(parts[0], out int id))
                {
                    errors.Add(new ImportError { RecordIndex = recordIndex, RawLine = line, ErrorMessage = "Invalid ID format." });
                    continue;
                }

                string name = parts[1].Trim();
                if (string.IsNullOrEmpty(name))
                {
                    errors.Add(new ImportError { RecordIndex = recordIndex, RawLine = line, ErrorMessage = "Name cannot be empty." });
                    continue;
                }

                if (!int.TryParse(parts[2], out int age) || age < 0 || age > 120)
                {
                    errors.Add(new ImportError { RecordIndex = recordIndex, RawLine = line, ErrorMessage = "Invalid age." });
                    continue;
                }

                string email = parts[3].Trim();
                if (!email.Contains("@") || !email.Contains("."))
                {
                    errors.Add(new ImportError { RecordIndex = recordIndex, RawLine = line, ErrorMessage = "Invalid email format." });
                    continue;
                }

                // If all validations pass, add to valid records
                validRecords.Add(new ImportRecord { Id = id, Name = name, Age = age, Email = email });
                Console.WriteLine($"  Successfully validated record {id}.");
            }
            catch (Exception ex) // Catch any unexpected system errors during parsing/validation
            {
                errors.Add(new ImportError { RecordIndex = recordIndex, RawLine = line, ErrorMessage = $"Unexpected parsing error: {ex.Message}" });
                // Log this exception for debugging internal code issues
                Console.Error.WriteLine($"  [FATAL PARSING ERROR] Record {recordIndex}: {ex.Message}");
                // We still continue, but acknowledge a deeper problem.
            }
        }

        Console.WriteLine("\n--- Import Summary ---");
        Console.WriteLine($"Total records processed: {recordIndex}");
        Console.WriteLine($"Valid records imported: {validRecords.Count}");
        Console.WriteLine($"Failed records: {errors.Count}");

        if (errors.Any())
        {
            Console.WriteLine("\n--- Details of Failed Records ---");
            foreach (var error in errors)
            {
                Console.WriteLine($"  Record #{error.RecordIndex} (Line: '{error.RawLine}') - Error: {error.ErrorMessage}");
            }
        }

        // Now, you can process validRecords (e.g., bulk insert into DB)
        // And optionally persist or report the 'errors' list.
    }

    public static void Main(string[] args)
    {
        List<string> dataLines = new List<string>
        {
            "1,Alice,30,alice@example.com",
            "2,Bob,abc,bob@example.com", // Invalid Age
            "3,Charlie,25,",              // Invalid Email (empty)
            "4,David,40,david.com",      // Invalid Email (missing @)
            "5,Eve,35,eve@example.com",
            "6,Frank,50",                // Too few fields (will hit IndexOutOfRangeException if not handled)
            "7,Grace,28,grace@example.com,ExtraField" // Too many fields
        };

        BulkImporter.ImportData(dataLines);
    }
}
```

This approach leads to a robust import process that handles common data quality issues gracefully without performance penalties or obscured code flow.

-----

### 5\. In a microservices environment, should timeouts and transient failures throw exceptions, or return a structured error response?

In a microservices environment, **timeouts and transient failures should generally return a structured error response (or an indicator that allows for retry logic) rather than propagating raw exceptions across service boundaries.**

**Why a Structured Error Response is Preferred:**

1.  **Service Contract:** Microservices communicate via well-defined contracts (APIs). An error response is part of that contract, indicating that the service processed the request but encountered a specific, expected operational issue. Raw exceptions are an implementation detail that shouldn't leak across service boundaries.
2.  **Interoperability:** Different microservices might be written in different languages or frameworks. Throwing a C\# `TimeoutException` from one service makes no sense to a Python or Java client. A standardized HTTP status code (e.g., 503 Service Unavailable, 408 Request Timeout) combined with a JSON error payload is universally understood.
3.  **Client Responsibility:** Returning a structured error response empowers the client service to handle the situation appropriately. For timeouts and transient failures, this often means implementing **retry logic** (with exponential backoff and jitter). If the client just receives an exception, it might not know if it's safe to retry.
4.  **Security:** Exposing raw exception details (like stack traces) in a response is a significant security risk, as it can reveal internal architecture, dependencies, and potential vulnerabilities.
5.  **Logging and Monitoring:** Structured error responses facilitate better logging and monitoring. Services can emit specific error codes and metrics for these types of failures, allowing for dashboards to track service health and retry success rates.
6.  **Granularity and Context:** A structured error response can provide more context than a simple exception. For a timeout, it might include:
      * `errorCode`: e.g., "SERVICE\_TIMEOUT", "DEPENDENCY\_UNAVAILABLE"
      * `message`: "Payment gateway did not respond within 5 seconds."
      * `retryable`: `true` (explicitly tells client to retry)
      * `details`: (optional) ID of the slow dependency.
      * `correlationId`: For tracing the request across services.

**When to still throw (internal to a service):**

Exceptions are still vital *within* a microservice for:

  * **Internal Bugs/Programming Errors:** If a developer makes a mistake (e.g., null reference, unhandled `IndexOutOfRangeException`), that's an exception indicating a bug that needs to be fixed. These usually become 500 Internal Server Error responses.
  * **Critical Unrecoverable Failures:** If a service cannot function at all (e.g., cannot connect to its own database), an exception is thrown internally, which then typically gets translated into a 500 response.

**Code Example (Conceptual):**

```csharp
// --- Service A (Calling Service) ---
public class OrderService
{
    private readonly PaymentServiceClient _paymentClient;

    public OrderService(PaymentServiceClient paymentClient)
    {
        _paymentClient = paymentClient;
    }

    public async Task<OrderProcessingResult> ProcessOrderAsync(Order order)
    {
        // ... (order validation)

        // Call Payment Service
        PaymentResponse paymentResponse = await _paymentClient.ProcessPaymentAsync(order.Amount, order.PaymentInfo);

        if (paymentResponse.IsSuccess)
        {
            // Payment successful, continue order fulfillment
            return new OrderProcessingResult { Status = OrderStatus.Success, Message = "Order processed successfully." };
        }
        else // Payment failed, check the structured error
        {
            if (paymentResponse.ErrorCode == "INSUFFICIENT_FUNDS")
            {
                return new OrderProcessingResult { Status = OrderStatus.Failed, Message = "Payment failed: Insufficient funds." };
            }
            else if (paymentResponse.ErrorCode == "PAYMENT_GATEWAY_TIMEOUT" && paymentResponse.IsRetryable)
            {
                // This is where retry logic would kick in
                Console.WriteLine($"[OrderService] Payment gateway timed out. Retrying order {order.Id}...");
                // (In real life, this would be handled by a Polly policy or similar)
                return new OrderProcessingResult { Status = OrderStatus.PendingRetry, Message = "Payment timed out, will retry." };
            }
            else // Other non-retryable or unexpected payment failures
            {
                Console.WriteLine($"[OrderService] Payment failed with unhandled error: {paymentResponse.ErrorCode} - {paymentResponse.ErrorMessage}");
                // Log the failure details
                return new OrderProcessingResult { Status = OrderStatus.Failed, Message = $"Payment failed: {paymentResponse.ErrorMessage}" };
            }
        }
    }
}

// --- Payment Service (Responding Service) ---
public class PaymentController // Example Web API controller
{
    [HttpPost("process")]
    public async Task<IActionResult> ProcessPayment([FromBody] PaymentRequest request)
    {
        try
        {
            // Simulate calling an external gateway
            GatewayResult gatewayResult = await _gateway.PerformTransaction(request);

            if (gatewayResult.Status == GatewayStatus.Success)
            {
                return Ok(new PaymentResponse { IsSuccess = true, Message = "Transaction approved." });
            }
            else if (gatewayResult.Status == GatewayStatus.InsufficientFunds)
            {
                // Business rule violation -> structured error response
                return BadRequest(new PaymentResponse { IsSuccess = false, ErrorCode = "INSUFFICIENT_FUNDS", ErrorMessage = "Account balance is too low." });
            }
            // ... other specific business rule failures

            // This is a timeout or transient failure from a dependency
            else if (gatewayResult.Status == GatewayStatus.Timeout || gatewayResult.Status == GatewayStatus.TemporaryUnavailable)
            {
                // Service is unavailable or timed out -> structured error response, indicate retryable
                return StatusCode(503, new PaymentResponse { IsSuccess = false, ErrorCode = "PAYMENT_GATEWAY_TIMEOUT", ErrorMessage = "Payment gateway did not respond in time.", IsRetryable = true });
            }
            else
            {
                // Any other unhandled gateway status
                return StatusCode(500, new PaymentResponse { IsSuccess = false, ErrorCode = "UNKNOWN_GATEWAY_ERROR", ErrorMessage = "An unexpected error occurred with the payment gateway." });
            }
        }
        catch (Exception ex) // Catch internal system exceptions
        {
            // Log the exception details internally
            Console.Error.WriteLine($"[PaymentService] Unhandled internal exception: {ex}");
            // Translate to a generic 500 Internal Server Error
            return StatusCode(500, new PaymentResponse { IsSuccess = false, ErrorCode = "INTERNAL_SERVER_ERROR", ErrorMessage = "An internal error occurred. Please try again later." });
        }
    }
}

// Data Transfer Objects (DTOs) for inter-service communication
public class PaymentRequest { /* ... */ }
public class PaymentResponse
{
    public bool IsSuccess { get; set; }
    public string? ErrorCode { get; set; }
    public string? ErrorMessage { get; set; }
    public bool IsRetryable { get; set; } // Crucial for transient failures
}

// Other supporting classes...
public class Order { public int Id { get; set; } public decimal Amount { get; set; } public string PaymentInfo { get; set; } }
public enum OrderStatus { Success, Failed, PendingRetry }
public class OrderProcessingResult { public OrderStatus Status { get; set; } public string Message { get; set; } = string.Empty; }
public enum GatewayStatus { Success, InsufficientFunds, Timeout, TemporaryUnavailable, OtherFailure }
public class GatewayResult { public GatewayStatus Status { get; set; } /* ... */ }
public class PaymentServiceClient { public Task<PaymentResponse> ProcessPaymentAsync(decimal amount, string info) => Task.FromResult(new PaymentResponse { IsSuccess = true }); } // Dummy client
```

This pattern promotes robust, resilient, and interoperable microservices that handle various failure types gracefully.