Let's break down the `try-catch-finally` block in C\#, which is fundamental for robust error handling and ensuring resource cleanup.

## `try-catch-finally` Flow: Control Flow and Execution Guarantees

The `try-catch-finally` construct in C\# is used for exception handling. It allows you to:

  * **`try`**: Define a block of code where exceptions might occur.
  * **`catch`**: Handle specific types of exceptions that are thrown within the `try` block.
  * **`finally`**: Execute a block of code regardless of whether an exception occurred or was handled. This is crucial for resource cleanup.

### Execution Order: `try` → `catch` → `finally`

The execution flow of a `try-catch-finally` block follows a strict order:

1.  **`try` block**: The code inside the `try` block is executed first.

      * **If no exception occurs**: The `try` block completes, and execution immediately transfers to the `finally` block (if present). The `catch` blocks are skipped.
      * **If an exception occurs**:
          * The execution of the `try` block is immediately stopped at the point the exception is thrown.
          * The Common Language Runtime (CLR) searches for a matching `catch` block.
          * If a matching `catch` block is found, its code is executed.
          * After the `catch` block completes, execution transfers to the `finally` block (if present).
          * If no matching `catch` block is found, the exception propagates up the call stack, potentially leading to program termination if it remains unhandled. However, before the program terminates, the `finally` block (if present) of any `try-catch-finally` block in the current stack frame will still execute.

2.  **`catch` block(s)**:

      * Only executed if an exception is thrown in the `try` block (or in a preceding `catch` block within a nested `try`).
      * The specific `catch` block whose exception type matches or is a base class of the thrown exception is executed.
      * After a `catch` block finishes, the `finally` block executes.

3.  **`finally` block**:

      * **Always executes**, regardless of whether an exception occurred, was caught, or propagated unhandled.
      * It's guaranteed to run before control leaves the `try-catch-finally` statement. This makes it ideal for cleanup code (e.g., closing file streams, releasing database connections, disposing of disposable objects).

**Code Example - Basic Flow:**

```csharp
using System;
using System.IO;

public static class TryCatchFinallyFlow
{
    public static void Run()
    {
        Console.WriteLine("--- Basic Try-Catch-Finally Flow ---");

        // Scenario 1: No exception
        Console.WriteLine("\nScenario 1: No Exception");
        PerformOperation(true); // Should not throw an exception

        // Scenario 2: Exception caught
        Console.WriteLine("\nScenario 2: Exception Caught");
        PerformOperation(false); // Should throw and catch an exception

        // Scenario 3: Exception not caught (propagates)
        Console.WriteLine("\nScenario 3: Exception Not Caught (Propagates)");
        try
        {
            // Simulate an unhandled exception to see finally still runs
            // Note: This will terminate the program if not caught higher up.
            // For demonstration, we wrap it in an outer try-catch.
            PerformOperationWithUnhandledException(true);
        }
        catch (FormatException ex)
        {
            Console.WriteLine($"[Outer Catch]: Caught propagated exception: {ex.Message}");
        }

        Console.WriteLine();
    }

    public static void PerformOperation(bool success)
    {
        Console.WriteLine("[Method]: Starting PerformOperation.");
        try
        {
            Console.WriteLine("[Try]: Entering try block.");
            if (!success)
            {
                Console.WriteLine("[Try]: Throwing new InvalidOperationException.");
                throw new InvalidOperationException("Something went wrong!");
            }
            Console.WriteLine("[Try]: Operation successful.");
        }
        catch (InvalidOperationException ex)
        {
            Console.WriteLine($"[Catch]: Caught exception: {ex.Message}");
        }
        finally
        {
            Console.WriteLine("[Finally]: Entering finally block.");
            // This code always executes, good for cleanup
            Console.WriteLine("[Finally]: Resource cleanup complete.");
        }
        Console.WriteLine("[Method]: Exiting PerformOperation.");
    }

    public static void PerformOperationWithUnhandledException(bool throwException)
    {
        Console.WriteLine("[Method]: Starting PerformOperationWithUnhandledException.");
        try
        {
            Console.WriteLine("[Try]: Entering try block.");
            if (throwException)
            {
                Console.WriteLine("[Try]: Throwing new FormatException (unhandled in this block).");
                throw new FormatException("This format is invalid!");
            }
            Console.WriteLine("[Try]: Operation successful.");
        }
        // No catch block for FormatException here
        finally
        {
            Console.WriteLine("[Finally]: Entering finally block in unhandled scenario.");
            Console.WriteLine("[Finally]: Performing cleanup even with unhandled exception.");
        }
        Console.WriteLine("[Method]: Exiting PerformOperationWithUnhandledException.");
    }
}
```

### What happens if an exception occurs inside `catch` or `finally`?

This is a critical point about `try-catch-finally` guarantees.

1.  **Exception inside `catch` block**:

      * If an exception occurs within a `catch` block, the original exception (the one that caused entry into the `catch` block) is **discarded**, and the *new exception* (thrown from within the `catch` block) is thrown up the call stack.
      * The `finally` block will still execute before the new exception propagates further.

2.  **Exception inside `finally` block**:

      * If an exception occurs within a `finally` block, it **overrides** any pending exception that might have been thrown in the `try` or `catch` blocks.
      * The new exception (from `finally`) is thrown up the call stack. The original exception is lost.
      * This is why `finally` blocks should be kept simple and contain only logic that is extremely unlikely to throw exceptions.

**Code Example - Exceptions in `catch` and `finally`:**

```csharp
using System;

public static class TryCatchFinallyExceptions
{
    public static void Run()
    {
        Console.WriteLine("--- Exceptions in Catch and Finally ---");

        // Scenario 1: Exception in catch block
        Console.WriteLine("\nScenario 1: Exception in Catch Block");
        try
        {
            MethodWithExceptionInCatch();
        }
        catch (DivideByZeroException ex) // Catches the exception from the catch block
        {
            Console.WriteLine($"[Outer Catch]: Caught exception from inner catch block: {ex.Message}");
        }

        // Scenario 2: Exception in finally block
        Console.WriteLine("\nScenario 2: Exception in Finally Block");
        try
        {
            MethodWithExceptionInFinally();
        }
        catch (NullReferenceException ex) // Catches the exception from the finally block
        {
            Console.WriteLine($"[Outer Catch]: Caught exception from finally block: {ex.Message}");
        }

        Console.WriteLine();
    }

    public static void MethodWithExceptionInCatch()
    {
        Console.WriteLine("[Method]: Entering MethodWithExceptionInCatch.");
        try
        {
            Console.WriteLine("[Try]: Throwing original ArgumentNullException.");
            throw new ArgumentNullException("Original exception from try");
        }
        catch (ArgumentNullException originalEx)
        {
            Console.WriteLine($"[Catch]: Caught original exception: {originalEx.Message}");
            Console.WriteLine("[Catch]: Now throwing new DivideByZeroException from inside catch.");
            // Original exception is discarded, new one propagates
            throw new DivideByZeroException("New exception from catch block!");
        }
        finally
        {
            Console.WriteLine("[Finally]: This finally block *still* executes.");
        }
        // This line is unreachable because of the exception propagation
        // Console.WriteLine("[Method]: Exiting MethodWithExceptionInCatch.");
    }

    public static void MethodWithExceptionInFinally()
    {
        Console.WriteLine("[Method]: Entering MethodWithExceptionInFinally.");
        try
        {
            Console.WriteLine("[Try]: Throwing original InvalidOperationException.");
            throw new InvalidOperationException("Original exception from try");
        }
        catch (InvalidOperationException originalEx)
        {
            Console.WriteLine($"[Catch]: Caught original exception: {originalEx.Message}");
        }
        finally
        {
            Console.WriteLine("[Finally]: Throwing new NullReferenceException from inside finally.");
            // Original exception (from try) is lost, this new exception propagates
            string s = null;
            Console.WriteLine(s.Length); // This will throw a NullReferenceException
        }
        // This line is unreachable
        // Console.WriteLine("[Method]: Exiting MethodWithExceptionInFinally.");
    }
}
```

### Multiple `catch` blocks

You can have multiple `catch` blocks to handle different types of exceptions specifically. When an exception is thrown, the CLR checks `catch` blocks in order from top to bottom. It executes the *first* `catch` block whose exception type matches or is a base class of the thrown exception.

**Important rules for multiple `catch` blocks:**

  * **Order Matters:** Specific exception types (`FileNotFoundException`, `DivideByZeroException`) must come *before* more general exception types (`IOException`, `Exception`). If `catch (Exception ex)` were first, it would catch everything, and subsequent more specific `catch` blocks would be unreachable.
  * **Polymorphism:** A `catch` block for a base class (e.g., `IOException`) will catch exceptions of derived types (e.g., `FileNotFoundException`).

**Code Example - Multiple `catch` blocks:**

```csharp
using System;
using System.IO;

public static class LinqMultipleCatch
{
    public static void Run()
    {
        Console.WriteLine("--- Multiple Catch Blocks ---");

        // Scenario 1: Catching a specific exception
        Console.WriteLine("\nScenario 1: Catching FileNotFoundException");
        PerformFileOperation(0); // Simulates FileNotFoundException

        // Scenario 2: Catching a more general exception
        Console.WriteLine("\nScenario 2: Catching IOException (base class)");
        PerformFileOperation(1); // Simulates DirectoryNotFoundException (derives from IOException)

        // Scenario 3: Catching a generic exception
        Console.WriteLine("\nScenario 3: Catching general Exception");
        PerformFileOperation(2); // Simulates InvalidOperationException

        // Scenario 4: No matching catch (propagates)
        Console.WriteLine("\nScenario 4: No matching catch (propagates)");
        try
        {
            PerformFileOperation(3); // Simulates ArgumentOutOfRangeException
        }
        catch (ArgumentOutOfRangeException ex)
        {
            Console.WriteLine($"[Outer Catch]: Caught propagated exception: {ex.Message}");
        }

        Console.WriteLine();
    }

    public static void PerformFileOperation(int scenario)
    {
        Console.WriteLine($"\n[Method]: Starting PerformFileOperation for scenario {scenario}.");
        try
        {
            if (scenario == 0)
            {
                // Specific exception
                Console.WriteLine("[Try]: Simulating FileNotFoundException.");
                throw new FileNotFoundException("File not found error!");
            }
            else if (scenario == 1)
            {
                // General IOException (DirectoryNotFoundException derives from it)
                Console.WriteLine("[Try]: Simulating DirectoryNotFoundException.");
                throw new DirectoryNotFoundException("Directory not found error!");
            }
            else if (scenario == 2)
            {
                // Generic Exception
                Console.WriteLine("[Try]: Simulating InvalidOperationException.");
                throw new InvalidOperationException("Some other operation failed!");
            }
            else if (scenario == 3)
            {
                // Unhandled exception in this block
                Console.WriteLine("[Try]: Simulating ArgumentOutOfRangeException.");
                throw new ArgumentOutOfRangeException("Index out of bounds!");
            }
            Console.WriteLine("[Try]: Operation successful.");
        }
        catch (FileNotFoundException ex) // Most specific
        {
            Console.WriteLine($"[Catch-FileNotFound]: Specific file error caught: {ex.Message}");
        }
        catch (IOException ex) // More general I/O error (catches DirectoryNotFoundException)
        {
            Console.WriteLine($"[Catch-IO]: General I/O error caught: {ex.Message}");
        }
        catch (InvalidOperationException ex) // Another specific non-I/O error
        {
            Console.WriteLine($"[Catch-InvalidOperation]: Specific operation error caught: {ex.Message}");
        }
        catch (Exception ex) // Catch-all (should be last)
        {
            Console.WriteLine($"[Catch-Generic]: Generic exception caught: {ex.GetType().Name} - {ex.Message}");
        }
        finally
        {
            Console.WriteLine("[Finally]: Cleanup for file operation.");
        }
        Console.WriteLine("[Method]: Exiting PerformFileOperation.");
    }
}
```

### 🧠 Interview Angle: Explain flow, nesting, and when `finally` block executes.

This is a comprehensive question that tests your understanding of exception handling nuances.

**1. Flow of `try-catch-finally`:**

  * **`try` block execution:** The code within the `try` block is executed first.
  * **No Exception:** If no exception occurs in the `try` block, the `catch` blocks are skipped, and control transfers directly to the `finally` block. After `finally` completes, execution continues with the code immediately following the `try-catch-finally` construct.
  * **Exception Occurs:**
      * Execution of the `try` block immediately stops at the point the exception is thrown.
      * The CLR searches for a suitable `catch` block (matching type or base type).
      * If a match is found: The code within the matching `catch` block executes. After the `catch` block completes, control transfers to the `finally` block.
      * If no match is found: The exception is considered unhandled within this `try-catch-finally` block. However, *before* the exception propagates up the call stack to a higher level handler (or causes program termination), the `finally` block *still* executes.
  * **`finally` block execution:** The `finally` block is **guaranteed to execute** in almost all circumstances, regardless of whether an exception occurred or was handled. It's the last part of the `try-catch-finally` construct to execute before control leaves the statement.

**2. Nesting `try-catch-finally` Blocks:**

You can nest `try-catch-finally` blocks within each other. This is useful when you have operations that might throw exceptions at different levels of abstraction or when you need to handle specific cleanup at different stages.

```csharp
public static void NestedTryCatchFinally()
{
    Console.WriteLine("--- Nested Try-Catch-Finally ---");
    try
    {
        Console.WriteLine("[Outer Try]: Entering outer try.");
        try
        {
            Console.WriteLine("[Inner Try]: Entering inner try.");
            throw new InvalidOperationException("Inner exception!");
            // Console.WriteLine("[Inner Try]: Inner operation successful.");
        }
        catch (InvalidOperationException innerEx)
        {
            Console.WriteLine($"[Inner Catch]: Caught inner exception: {innerEx.Message}");
            // Can rethrow, throw new exception, or handle and continue
            // throw; // Rethrows the innerEx
            // throw new Exception("New exception from inner catch");
        }
        finally
        {
            Console.WriteLine("[Inner Finally]: Executing inner finally.");
        }
        Console.WriteLine("[Outer Try]: Inner block completed without propagating unhandled exception.");
        // If inner catch rethrows, this line might not be reached or outer catch will handle
    }
    catch (Exception outerEx)
    {
        Console.WriteLine($"[Outer Catch]: Caught outer exception: {outerEx.Message}");
    }
    finally
    {
        Console.WriteLine("[Outer Finally]: Executing outer finally.");
    }
    Console.WriteLine("--- Nested Try-Catch-Finally End ---");
}
// You'd call NestedTryCatchFinally() in your Main method for demonstration.
```

When an exception occurs in an inner `try` block:

  * The inner `catch` blocks are checked.
  * The inner `finally` block always executes.
  * If the inner `catch` handles the exception, execution continues after the inner `finally`.
  * If the inner `catch` *doesn't* handle it (or re-throws), the exception propagates to the outer `try-catch-finally` block, and the outer `catch` blocks are then checked. The outer `finally` still executes last.

**3. When `finally` block executes:**

The `finally` block is designed to provide guaranteed execution for cleanup code. It executes in the following scenarios:

  * **Normal completion of `try` block:** No exception occurs.
  * **After a `catch` block executes:** An exception occurred in `try` and was successfully handled by a `catch` block.
  * **When an exception is unhandled/propagating:** An exception occurred in `try` (or `catch`), and there was no matching `catch` block within the current `try-catch-finally` or it was re-thrown. The `finally` block executes just before the exception continues propagating up the call stack.
  * **When returning from `try` or `catch`:** If there's a `return` statement within the `try` or `catch` block, the `finally` block will execute *before* the method actually returns control to the caller.
  * **When `break` or `continue` from `try` block:** If `try` is inside a loop and `break` or `continue` statements are hit, the `finally` block will still execute before the loop control transfers.
  * **Even in the face of resource disposal issues or other exceptions**: If an exception occurs within a `catch` block or even within the `finally` block itself, the `finally` block (or the part of it before its own exception) will still attempt to execute. (Though, as discussed, an exception in `finally` will override previous ones).

**Exceptions to `finally` execution (Extremely Rare):**

The `finally` block is *almost* always guaranteed. Edge cases where it might not run include:

  * **Stack Overflow:** If a `StackOverflowException` occurs, the CLR might not have enough stack space to execute `finally` blocks.
  * **Fatal Errors:** Certain critical system errors (like `OutOfMemoryException` in very extreme low-memory situations, although it often still runs) or hardware failures.
  * **`Environment.FailFast()`:** Explicitly terminates the process without unwinding the stack.
  * **External Termination:** The process is killed externally (e.g., Task Manager, operating system shutdown).

For typical application logic, you can rely on `finally` for cleanup.