Let's explore some of the critical nuances and potential pitfalls of `try-catch-finally` blocks in C\#, along with best practices for handling exceptions effectively.

-----

### ðŸ”¹ A method has a `return` statement inside both the `try` and `finally` blocks. What will actually be returned?

(The value from `finally` overrides the one from `try` â€” this is a dangerous practice.)

**Explanation:**

The `finally` block is guaranteed to execute *after* the `try` block, even if the `try` block contains a `return` statement. If a `finally` block also contains a `return` statement, it will override the `return` value from the `try` block.

**Pitfall:** This behavior is extremely counter-intuitive and can lead to bugs that are difficult to diagnose. While technically possible, returning from a `finally` block is almost universally considered a **dangerous practice** and should be avoided. The `finally` block is intended for cleanup, not controlling the return value of a method.

**Code Example:**

```csharp
using System;

public static class ReturnInFinally
{
    public static int GetValue()
    {
        try
        {
            Console.WriteLine("[Try]: Returning 10.");
            return 10; // This return value is prepared
        }
        finally
        {
            Console.WriteLine("[Finally]: Returning 99 (overrides try return).");
            return 99; // This return statement executes and overrides the previous one
        }
    }

    public static void Run()
    {
        Console.WriteLine("--- Return in Try and Finally ---");
        int result = GetValue();
        Console.WriteLine($"Actual return value: {result}"); // Output: 99
        Console.WriteLine();
    }
}
```

-----

### ðŸ”¹ Youâ€™re closing a file stream inside the `finally` block. If the stream object is `null`, what can go wrong and how do you fix it?

(A `NullReferenceException` can occur â€” add a null check (`if (stream != null)`) or use `?.Dispose()` or, preferably, the `using` statement.)

**Problem:**

A common pattern is to initialize a resource (like a `StreamReader`) in the `try` block and close it in the `finally` block. If the initialization fails (e.g., the file is locked, or the path is invalid) before the stream object is assigned, the object reference will remain `null`. When the `finally` block attempts to call `.Close()` or `.Dispose()` on the `null` object, it throws a `NullReferenceException`.

**Solution and Best Practice (`using` statement):**

The idiomatic way to handle disposable resources in C\# is by using the `using` statement (since C\# 8, `using` declarations are also available). The `using` statement ensures that `Dispose()` is called automatically, even if an exception occurs, and handles null scenarios safely.

**Code Example:**

```csharp
using System;
using System.IO;

public static class NullStreamInFinally
{
    public static void Run()
    {
        Console.WriteLine("--- Handling Null Stream in Finally ---");

        // Scenario 1: Demonstrating the NullReferenceException pitfall
        Console.WriteLine("\nScenario 1: Potential NullReferenceException in Finally");
        FileStream stream = null; // Declare outside try to make it visible to finally
        try
        {
            // Simulate an error before stream initialization
            Console.WriteLine("[Try]: Simulating an error during resource creation.");
            throw new Exception("Initialization failure.");
            // stream = File.Open("validpath.txt", FileMode.Open); // This line is skipped
        }
        catch (Exception ex)
        {
            Console.WriteLine($"[Catch]: Caught exception: {ex.Message}");
        }
        finally
        {
            // If stream is null due to the exception above, this throws NullReferenceException
            // stream.Close(); // DANGEROUS!
            Console.WriteLine("[Finally]: (Skipping stream.Close() due to NullReferenceException risk)");
        }

        // Scenario 2: Fix using explicit null check (or null-conditional operator)
        Console.WriteLine("\nScenario 2: Fixed using null check or using declaration");
        // We can safely dispose using the null-conditional operator (?.Dispose())
        stream?.Dispose(); 

        // Preferred solution: The 'using' statement
        try
        {
            Console.WriteLine("[Try]: Using 'using' declaration for safer disposal.");
            // The object will be automatically disposed at the end of the block, 
            // even if exceptions occur.
            using var safeStream = new MemoryStream();
            Console.WriteLine("[Try]: Stream created successfully.");
        }
        catch (Exception ex)
        {
            Console.WriteLine($"[Catch]: Caught exception: {ex.Message}");
        }
        // No finally block needed for disposal when using 'using'
        Console.WriteLine("[Finally]: 'using' handled disposal automatically.");
        
        Console.WriteLine();
    }
}
```

-----

### ðŸ”¹ You use `try-catch` around a method that already handles its own exceptions. What risks or redundancies does this create?

(Swallowing exceptions silently, double-handling, breaking single-responsibility.)

**Risks and Redundancies:**

1.  **Swallowing Exceptions Silently:** If the inner method catches an exception and handles it (e.g., logs it and continues), the outer `try-catch` might not even be aware an exception occurred. More dangerously, if the inner method throws an exception, and the outer `catch` block is empty or simply logs it and continues (`catch (Exception)`), you lose visibility into the error and the intended flow of the application is altered without notification.
2.  **Double-Handling/Redundancy:** If both blocks log the same exception, your logs become cluttered. If the inner method is responsible for error recovery, the outer block's handling may be redundant or incorrect.
3.  **Breaking Single Responsibility:** Each method or component should be responsible for handling the exceptions it can logically recover from. Wrapping a method that already has exception handling breaks this principle and makes the code harder to reason about.

-----

### ðŸ”¹ A team member puts business logic inside the `finally` block. What would you suggest?

(Warn against it: `finally` should only handle cleanup, not logic that could throw or control flow.)

**Explanation:**

The `finally` block exists solely to ensure that necessary cleanup actions (like closing connections, releasing locks, or disposing objects) are performed, regardless of the outcome of the `try` block.

Putting business logic (e.g., updating a database record, complex calculations, validating data) inside `finally` is poor practice because:

  * **It Violates Purpose:** It muddles the clear separation between business logic (in `try`/`catch`) and cleanup (in `finally`).
  * **Risks Exceptions During Cleanup:** If the business logic in `finally` throws an exception, it will suppress any exception that was already propagating from the `try` or `catch` blocks, making debugging extremely difficult.
  * **Interferes with Control Flow:** `finally` executes after `try` but before the method returns. Complex logic in `finally` can interfere with the intended execution path, especially if `return`, `break`, or `continue` statements are used within the `try` block.

-----

### ðŸ”¹ Inside a `catch`, a logging method throws its own exception (e.g., the logging service is down). The main exception is lost. How do you preserve it?

(Use `try-catch` inside `catch`; or log safely; or use `ExceptionDispatchInfo.Capture().Throw()` in advanced cases.)

**Problem:**

When an exception is thrown in the `try` block, you enter the `catch` block. If a *new* exception occurs within the `catch` block (e.g., when trying to log the original exception), the new exception **replaces** the original exception in the stack trace. The original exception is lost.

**Solutions:**

1.  **Log Safely (Best Practice):** Ensure your logging mechanism is robust and does not throw exceptions. Logging should be fault-tolerant.

2.  **`try-catch` inside the `catch` block:** Wrap the potentially dangerous logging call in its own `try-catch` block inside the main `catch`. This ensures the logging failure doesn't prevent the original exception from being handled or rethrown.

    ```csharp
    try
    {
        // Business logic that might fail
    }
    catch (Exception originalEx)
    {
        try
        {
            // Attempt logging the original exception
            Logger.Log(originalEx);
        }
        catch (Exception logEx)
        {
            // Handle logging failure separately (e.g., log to console, ignore)
            Console.Error.WriteLine($"Warning: Failed to log exception: {logEx.Message}");
        }

        // Re-throw the original exception to continue propagation
        throw; 
    }
    ```

3.  **`ExceptionDispatchInfo.Capture()` (Advanced):** This is used for advanced scenarios where you need to preserve the full stack trace and state of an exception and rethrow it later from a different context.

-----

### ðŸ”¹ You need to ensure a database connection is closed, even if an exception occurs during execution. What is your approach?

(Use `try-finally` or better, a `using` block which is safer and cleaner.)

**Approach:**

Database connections implement the `IDisposable` interface. The goal is to guarantee that the `Dispose()` method (which includes closing the connection) is called.

**1. Using `try-finally`:**

```csharp
using System.Data.SqlClient;

public void AccessData(string connectionString)
{
    SqlConnection connection = null; 
    try
    {
        connection = new SqlConnection(connectionString);
        connection.Open();
        // ... perform database operations ...
    }
    catch (SqlException ex)
    {
        // Handle database-specific errors
    }
    finally
    {
        // This guarantees disposal, even if an exception occurred in the try block
        if (connection != null)
        {
            connection.Close();
            connection.Dispose();
        }
    }
}
```

**2. Using `using` (Preferred and Cleaner):**

The `using` statement is syntactical sugar for the `try-finally` pattern specifically designed for `IDisposable` objects.

```csharp
using System.Data.SqlClient;

public void AccessData(string connectionString)
{
    // The using statement ensures Dispose() is called on the connection 
    // when the block is exited, regardless of exceptions.
    using (SqlConnection connection = new SqlConnection(connectionString))
    {
        try
        {
            connection.Open();
            // ... perform database operations ...
        }
        catch (SqlException ex)
        {
            // Handle database-specific errors
        }
    } // Connection is automatically closed/disposed here
}
```

-----

### ðŸ”¹ What happens if both the `try` and `finally` blocks throw exceptions? Which one is preserved?

(The exception in `finally` suppresses the one in `try`; this can make debugging very difficult.)

**Explanation:**

If the `try` block throws an exception, and subsequently the `finally` block also throws an exception, the exception from the `finally` block **overrides** and replaces the original exception from the `try` block.

The original exception is lost from the stack trace (unless you manually capture it using `ExceptionDispatchInfo`), and only the exception thrown by `finally` is propagated up the call stack.

This is a major reason why `finally` blocks should be kept simple and focused strictly on cleanup that is unlikely to throw exceptions. If cleanup code *might* throw an exception, it should be wrapped in its own `try-catch` inside the `finally` block.

**Code Example:**

```csharp
using System;

public static class FinallySupressesException
{
    public static void MethodWithExceptions()
    {
        try
        {
            Console.WriteLine("[Try]: Throwing InvalidOperationException.");
            throw new InvalidOperationException("Exception from Try block (A)");
        }
        finally
        {
            Console.WriteLine("[Finally]: Throwing NullReferenceException.");
            // This exception suppresses and replaces the InvalidOperationException (A)
            throw new NullReferenceException("Exception from Finally block (B)");
        }
    }

    public static void Run()
    {
        Console.WriteLine("--- Finally Suppresses Try Exception ---");
        try
        {
            MethodWithExceptions();
        }
        catch (Exception ex)
        {
            Console.WriteLine($"[Outer Catch]: Caught exception of type: {ex.GetType().Name}");
            Console.WriteLine($"[Outer Catch]: Message: {ex.Message}");
            // The caught exception will be the NullReferenceException (B) from the finally block.
        }
        Console.WriteLine();
    }
}
```