Let's break down these scenarios related to advanced exception safety, focusing on common pitfalls and best practices.

-----

### ðŸ”¹ Youâ€™re reading from a file and writing to a database. If an exception occurs midway, how do you ensure both resources are released properly?

(Use nested `using` blocks or a `try-finally` with disposal logic.)

**Explanation:**

When dealing with multiple disposable resources (like file streams and database connections), it's crucial to ensure *all* of them are properly released, even if an operation on one of them (or an intermediate operation) throws an exception.

**Preferred Method: Nested `using` statements**

The `using` statement is the most idiomatic and safest way to handle `IDisposable` resources in C\#. When you nest them, the inner resource is disposed first, then the outer resource, guaranteeing cleanup in the correct order.

**Code Example (Nested `using`):**

```csharp
using System;
using System.Data.SqlClient; // Using a common DB connection type
using System.IO;

public static class ResourceCleanupExample
{
    public static void Run()
    {
        Console.WriteLine("--- Nested using Blocks for Resource Release ---");

        // Prepare a dummy file for reading
        File.WriteAllText("input.txt", "Line 1\nLine 2\nLine 3\nLine 4");

        // Scenario 1: Successful operation
        Console.WriteLine("\nScenario 1: Successful file read and DB write.");
        try
        {
            ProcessFileToDatabase("input.txt", "success_connection_string", false);
            Console.WriteLine("  Operation completed successfully. Resources released.");
        }
        catch (Exception ex)
        {
            Console.WriteLine($"  Unexpected exception in Scenario 1: {ex.Message}");
        }

        // Scenario 2: Exception during file read
        Console.WriteLine("\nScenario 2: Exception during file read (simulated).");
        try
        {
            // Simulate an error during file reading (e.g., file corrupted, permissions)
            ProcessFileToDatabase("nonexistent.txt", "success_connection_string", false);
            Console.WriteLine("  Operation completed successfully. (Should not happen)");
        }
        catch (FileNotFoundException ex)
        {
            Console.WriteLine($"  Caught expected file exception: {ex.Message}");
            Console.WriteLine("  File stream guaranteed to be closed.");
        }
        catch (Exception ex)
        {
            Console.WriteLine($"  Unexpected exception in Scenario 2: {ex.Message}");
        }

        // Scenario 3: Exception during database write
        Console.WriteLine("\nScenario 3: Exception during database write (simulated).");
        try
        {
            ProcessFileToDatabase("input.txt", "bad_connection_string", true); // Simulate DB error
            Console.WriteLine("  Operation completed successfully. (Should not happen)");
        }
        catch (InvalidOperationException ex) // Our simulated DB error
        {
            Console.WriteLine($"  Caught expected DB exception: {ex.Message}");
            Console.WriteLine("  Both file stream AND DB connection guaranteed to be closed.");
        }
        catch (Exception ex)
        {
            Console.WriteLine($"  Unexpected exception in Scenario 3: {ex.Message}");
        }

        // Clean up dummy file
        File.Delete("input.txt");
        Console.WriteLine();
    }

    public static void ProcessFileToDatabase(string filePath, string dbConnectionString, bool simulateDbError)
    {
        // Outer using block for the file stream
        using (FileStream fs = new FileStream(filePath, FileMode.Open, FileAccess.Read))
        using (StreamReader reader = new StreamReader(fs)) // Can chain using statements for related disposables
        {
            Console.WriteLine($"  [Read]: File '{filePath}' opened.");

            // Inner using block for the database connection
            using (SqlConnection connection = new SqlConnection(dbConnectionString))
            {
                Console.WriteLine($"  [DB]: Attempting to open DB connection '{dbConnectionString}'.");
                connection.Open(); // This might throw if connection string is bad
                Console.WriteLine("  [DB]: DB connection opened.");

                string line;
                int lineNumber = 0;
                while ((line = reader.ReadLine()) != null)
                {
                    lineNumber++;
                    Console.WriteLine($"    [Read Line]: Processing line {lineNumber}: {line}");

                    // Simulate writing to database
                    if (simulateDbError && lineNumber == 2)
                    {
                        Console.WriteLine("      [DB]: Simulating database write error on line 2...");
                        throw new InvalidOperationException("Simulated database write failure!");
                    }

                    // In a real app, use SqlCommand etc.
                    // Console.WriteLine($"      [DB]: Writing line {lineNumber} to database...");
                }
                Console.WriteLine($"  [DB]: All lines processed/written.");
            } // connection.Dispose() is implicitly called here (even if an exception occurred within its block)
            Console.WriteLine("  [DB]: DB connection guaranteed to be closed.");
        } // fs.Dispose() and reader.Dispose() are implicitly called here
        Console.WriteLine($"  [Read]: File stream guaranteed to be closed.");
    }
}
```

**Alternative (`try-finally`):**

While `using` is preferred, you can achieve the same with nested `try-finally` blocks. This is useful if you cannot use `using` (e.g., if the resource is returned from a method and needs to be disposed later in a different scope) or if you need more complex setup/teardown.

```csharp
// Example using try-finally (less idiomatic for this exact scenario, but functionally equivalent)
public static void ProcessFileToDatabaseManual(string filePath, string dbConnectionString, bool simulateDbError)
{
    FileStream fs = null;
    StreamReader reader = null;
    SqlConnection connection = null;

    try
    {
        fs = new FileStream(filePath, FileMode.Open, FileAccess.Read);
        reader = new StreamReader(fs);
        Console.WriteLine($"  [Read]: File '{filePath}' opened.");

        connection = new SqlConnection(dbConnectionString);
        Console.WriteLine($"  [DB]: Attempting to open DB connection '{dbConnectionString}'.");
        connection.Open();
        Console.WriteLine("  [DB]: DB connection opened.");

        string line;
        int lineNumber = 0;
        while ((line = reader.ReadLine()) != null)
        {
            lineNumber++;
            Console.WriteLine($"    [Read Line]: Processing line {lineNumber}: {line}");

            if (simulateDbError && lineNumber == 2)
            {
                Console.WriteLine("      [DB]: Simulating database write error on line 2...");
                throw new InvalidOperationException("Simulated database write failure!");
            }
        }
        Console.WriteLine($"  [DB]: All lines processed/written.");
    }
    finally // This ensures cleanup regardless of exceptions
    {
        // Dispose resources in reverse order of acquisition (if possible)
        if (connection != null)
        {
            Console.WriteLine("  [DB Cleanup]: Closing DB connection.");
            try { connection.Dispose(); }
            catch (Exception disposeEx) { Console.WriteLine($"    Error during DB dispose: {disposeEx.Message}"); }
        }
        if (reader != null)
        {
            Console.WriteLine("  [Read Cleanup]: Closing file reader.");
            try { reader.Dispose(); }
            catch (Exception disposeEx) { Console.WriteLine($"    Error during reader dispose: {disposeEx.Message}"); }
        }
        if (fs != null) // Redundant if reader disposes fs, but good for illustration
        {
            Console.WriteLine("  [Read Cleanup]: Closing file stream.");
            try { fs.Dispose(); }
            catch (Exception disposeEx) { Console.WriteLine($"    Error during file stream dispose: {disposeEx.Message}"); }
        }
    }
}
```

**Why `using` is preferred:** It's more concise, less error-prone (you can't forget `Dispose()`), and the compiler handles the `try-finally` translation for you.

-----

### ðŸ”¹ An async method fails but doesn't throw in your try-catch. You see `Task.Exception` is set. Whatâ€™s going wrong?

(The task wasnâ€™t awaited â€” exception is unobserved. Always `await` async calls to catch failures.)

**Explanation:**

This is a common pitfall in `async`/`await` programming. When an `async` method throws an exception, that exception is captured and stored within the `Task` object it returns. The exception is only re-thrown on the calling context when the `Task` is **`await`ed**.

If you start an `async` method but do not `await` its `Task` (often referred to as "fire and forget"), and that method throws an exception, the exception will be stored in the `Task.Exception` property. In .NET Core and modern .NET, these "unobserved exceptions" (exceptions in unawaited tasks) *do not* crash the process by default (unlike older .NET Framework versions). Instead, they are simply logged or remain unhandled, leading to silent failures where you know an error occurred (because `Task.Exception` is set) but your `try-catch` block wasn't triggered.

**What went wrong:**

You likely have code that looks like this:

```csharp
// Somewhere in your code
public async Task MyCallingMethod()
{
    try
    {
        DoSomethingAsyncThatMightFail(); // <-- MISSING 'await'
        Console.WriteLine("This line might still execute even if DoSomethingAsyncThatMightFail throws!");
    }
    catch (Exception ex)
    {
        Console.WriteLine($"Caught: {ex.Message}"); // This catch block will NOT be hit.
    }
}

private async Task DoSomethingAsyncThatMightFail()
{
    Console.WriteLine("Inside async method that will fail.");
    await Task.Delay(10);
    throw new InvalidOperationException("Failed inside the async method!");
}
```

Because `DoSomethingAsyncThatMightFail()` is not `await`ed, it returns a `Task` that represents the ongoing (and eventually faulted) operation. The `try-catch` block around the call to `DoSomethingAsyncThatMightFail()` only catches exceptions thrown synchronously *before* the first `await` or if the method completes synchronously. It doesn't monitor the `Task` for its eventual faulted state.

**Solution: Always `await` your `Task`s:**

To ensure exceptions from `async` methods are correctly propagated and caught, you must `await` the `Task` they return.

**Code Example:**

```csharp
using System;
using System.Threading.Tasks;

public static class UnawaitedTaskExample
{
    public static async Task Run()
    {
        Console.WriteLine("--- Unawaited Task Exception ---");

        // Scenario 1: Incorrect - Fire and forget
        Console.WriteLine("\nScenario 1: Incorrect - Fire and forget (exception unobserved)");
        try
        {
            FireAndForgetAsyncMethod(); // Not awaited!
            Console.WriteLine("  Fire and forget call returned. Main method continues.");
            await Task.Delay(100); // Give time for the async method to complete/fault
            // At this point, the Task returned by FireAndForgetAsyncMethod() has Task.Exception set,
            // but the try-catch here did not catch it.
        }
        catch (Exception ex)
        {
            Console.WriteLine($"  [Caught in Main]: This will NOT be hit by the F&F method's exception: {ex.Message}");
        }
        Console.WriteLine("  Check if the 'FireAndForgetAsyncMethod' exception was truly unobserved in TaskScheduler.UnobservedTaskException.");
        // You'd typically log TaskScheduler.UnobservedTaskException for such cases to debug.
        // For demonstration, let's explicitly grab the task and show its exception
        Task unobservedTask = FireAndForgetAsyncMethod(); // Store the task explicitly
        await Task.Delay(100);
        if (unobservedTask.IsFaulted)
        {
             Console.WriteLine($"  Manually checked unobservedTask.Exception: {unobservedTask.Exception.InnerException.Message}");
        }


        // Scenario 2: Correct - Await the async method
        Console.WriteLine("\nScenario 2: Correct - Await the async method (exception caught)");
        try
        {
            await CorrectlyAwaitedAsyncMethod(); // Awaited!
            Console.WriteLine("  Awaited call completed. (Should not happen)");
        }
        catch (InvalidOperationException ex)
        {
            Console.WriteLine($"  [Caught in Main]: Successfully caught expected exception: {ex.Message}");
        }
        catch (Exception ex)
        {
            Console.WriteLine($"  [Caught in Main]: Unexpected exception: {ex.Message}");
        }

        Console.WriteLine();
    }

    // This method simulates an async operation that throws
    private static async Task FireAndForgetAsyncMethod()
    {
        Console.WriteLine("    [F&F Method]: Starting operation...");
        await Task.Delay(50);
        Console.WriteLine("    [F&F Method]: Throwing exception!");
        throw new InvalidOperationException("Exception from Fire-and-Forget method!");
    }

    private static async Task CorrectlyAwaitedAsyncMethod()
    {
        Console.WriteLine("    [Awaited Method]: Starting operation...");
        await Task.Delay(50);
        Console.WriteLine("    [Awaited Method]: Throwing exception!");
        throw new InvalidOperationException("Exception from Awaited method!");
    }
}
```

**Mitigation for Fire-and-Forget (if truly intended):**

If you genuinely need a fire-and-forget task (e.g., for background processing), you *must* explicitly handle its potential exceptions within the async method itself, or attach a continuation to log them:

```csharp
// Mitigation for fire-and-forget
public async Task FireAndForgetWithExceptionLogging()
{
    try
    {
        await Task.Delay(50);
        throw new InvalidOperationException("Exception from Fire-and-Forget with logging!");
    }
    catch (Exception ex)
    {
        // Log the exception here, as it won't propagate to the caller
        Console.WriteLine($"  [F&F Logger]: Caught and logged exception: {ex.Message}");
    }
}

// Or using ContinueWith
public void FireAndForgetWithContinueWith()
{
    Task.Run(async () =>
    {
        await Task.Delay(50);
        throw new InvalidOperationException("Exception from F&F with ContinueWith!");
    })
    .ContinueWith(t =>
    {
        if (t.IsFaulted)
        {
            Console.WriteLine($"  [F&F ContinueWith]: Task faulted with: {t.Exception.InnerException.Message}");
        }
    }, TaskContinuationOptions.OnlyOnFaulted); // Only run if the task faulted
}
```

-----

### ðŸ”¹ You use `Task.WhenAll()` on 5 HTTP calls and catch a single exception. Later, you learn 3 of them failed. What did you miss?

(Didnâ€™t inspect `AggregateException.InnerExceptions` â€” `WhenAll` wraps multiple faults.)

**Explanation:**

When you `await Task.WhenAll(task1, task2, ..., taskN)`, and multiple of those tasks fail, the `await` expression will throw a single `AggregateException`. This `AggregateException` will contain *all* the exceptions from the faulted tasks within its `InnerExceptions` collection.

**What you missed:**

You likely only inspected the top-level `AggregateException.Message` or assumed its `InnerException` property would contain the only failure, which is only true if *exactly one* task failed. You need to iterate through the `AggregateException.InnerExceptions` collection to see all the individual faults.

**Code Example:**

```csharp
using System;
using System.Net.Http;
using System.Threading.Tasks;
using System.Linq; // For .Select()

public static class WhenAllMultipleFailures
{
    public static async Task Run()
    {
        Console.WriteLine("--- Task.WhenAll() with Multiple Failures ---");

        // Create a list of tasks, some of which will fail
        var tasks = new List<Task<string>>();
        tasks.Add(SimulateHttpCall(1, false)); // Success
        tasks.Add(SimulateHttpCall(2, true, "Timeout for Call 2")); // Failure 1
        tasks.Add(SimulateHttpCall(3, false)); // Success
        tasks.Add(SimulateHttpCall(4, true, "Network down for Call 4")); // Failure 2
        tasks.Add(SimulateHttpCall(5, true, "Unauthorized for Call 5")); // Failure 3

        try
        {
            Console.WriteLine("Awaiting Task.WhenAll on multiple HTTP calls...");
            string[] results = await Task.WhenAll(tasks);
            Console.WriteLine($"  All {results.Length} calls succeeded."); // This line won't be reached
        }
        catch (AggregateException agEx)
        {
            Console.WriteLine($"  [Caught]: AggregateException encountered!");
            Console.WriteLine($"  Total inner exceptions: {agEx.InnerExceptions.Count}"); // This will be 3

            // CORRECT: Iterate through InnerExceptions to see all failures
            foreach (var innerEx in agEx.InnerExceptions)
            {
                Console.WriteLine($"    - Inner Exception Type: {innerEx.GetType().Name}, Message: {innerEx.Message}");
                // You can also inspect innerEx.StackTrace for detailed debugging
            }

            // OPTIONAL: Using Flatten() for nested AggregateExceptions and Handle() for selective processing
            // var flattenedEx = agEx.Flatten();
            // flattenedEx.Handle(ex =>
            // {
            //     // Handle specific types of errors, return true if handled
            //     return false; // For this example, we just list them.
            // });
        }
        catch (Exception ex)
        {
            Console.WriteLine($"  [Caught]: Unexpected non-AggregateException: {ex.Message}");
        }

        Console.WriteLine();
    }

    private static async Task<string> SimulateHttpCall(int callId, bool shouldFail, string errorMessage = null)
    {
        Console.WriteLine($"  [Call {callId}]: Starting HTTP call...");
        await Task.Delay(50); // Simulate network latency

        if (shouldFail)
        {
            Console.WriteLine($"  [Call {callId}]: Simulating failure: {errorMessage}");
            throw new HttpRequestException(errorMessage);
        }

        Console.WriteLine($"  [Call {callId}]: Succeeded.");
        return $"Response from Call {callId}";
    }
}
```

-----

### ðŸ”¹ You log exceptions from multiple failed tasks using `Task.WhenAll()`, but only the first message appears. Why?

(You accessed only the root exception message â€” must flatten or iterate `InnerExceptions`.)

**Explanation:**

This is a direct follow-up to the previous point. If you write your logging code like this:

```csharp
try
{
    await Task.WhenAll(tasks);
}
catch (AggregateException agEx)
{
    // Incorrect logging: Only logs the AggregateException's own message, which is generic
    // And its default InnerException will be just the *first* one.
    Logger.Error($"Task.WhenAll failed: {agEx.Message}"); // This is the problem!
}
```

The `agEx.Message` property of an `AggregateException` is typically a generic message like "One or more errors occurred." It does *not* concatenate the messages of all inner exceptions. If you want the messages of all the individual failures, you must explicitly iterate through `agEx.InnerExceptions`.

**Solution:**

Iterate through `agEx.InnerExceptions` and log each one. You might also want to use `agEx.Flatten()` if there's a possibility of nested `AggregateException`s (though less common with direct `WhenAll` calls).

**Code Example (Refer to "Scenario 2: Multiple exceptions from Task.WhenAll() with Flatten() and Handle()" in the `AggregateExceptionExample` above, which correctly iterates through and prints messages of all inner exceptions.)**

```csharp
// ... (Previous setup for Task.WhenAll with multiple failures) ...

        try
        {
            await Task.WhenAll(tasks);
        }
        catch (AggregateException agEx)
        {
            Console.WriteLine($"  [Logger]: Task.WhenAll failed. Here are the detailed errors:");

            // Correct way to log all inner exceptions:
            foreach (var innerEx in agEx.InnerExceptions)
            {
                Console.WriteLine($"    Error: [{innerEx.GetType().Name}] {innerEx.Message}");
                // For full details, you'd log innerEx.ToString() or innerEx.StackTrace
                // Logger.Error(innerEx, "Individual task failed in Task.WhenAll");
            }

            // If there's a chance of nested AggregateExceptions (e.g., from parallel LINQ inside tasks),
            // you might want to flatten first:
            // var flattenedExceptions = agEx.Flatten().InnerExceptions;
            // foreach (var ex in flattenedExceptions) { /* log ex */ }
        }
```

-----

### ðŸ”¹ Your app occasionally crashes with unhandled exceptions from background tasks. Whatâ€™s your mitigation strategy?

(Use exception-safe task wrappers, attach `.ContinueWith()`, or use `try-catch` inside async lambdas.)

**Explanation:**

Background tasks (often "fire and forget" `Task`s, or tasks created by `Task.Run()` without being `await`ed by the main flow) are notorious for causing crashes if their exceptions are not handled. In older .NET Framework versions, an unobserved exception on an unawaited task would by default terminate the process. In modern .NET Core/.NET 5+, this default behavior changed (they are observed but don't crash by default), but they still represent unhandled errors that can lead to data corruption or silent failures.

**Mitigation Strategies:**

1.  **Always `await` (The Best Approach):**

      * If possible, `await` your background task. Even if you don't need its result immediately, `await`ing it (perhaps later, or at an application shutdown point) ensures its exceptions are re-thrown and can be caught.
      * If the calling method is not `async`, make it `async void` *only* for event handlers (where `await` isn't an option for the caller). For other scenarios, it's generally best to keep the `Task` and `await` it.

2.  **`try-catch` within the `async` Lambda/Method:**

      * This is the most direct way to ensure the background task itself handles its own exceptions. The `catch` block prevents the exception from reaching the `Task` object as an unobserved fault.

3.  **`Task.ContinueWith(..., TaskContinuationOptions.OnlyOnFaulted)`:**

      * Attach a continuation to the background `Task` that specifically executes only if the task faults. This continuation can then log the exception.

4.  **Global `TaskScheduler.UnobservedTaskException` Event (for auditing):**

      * Subscribe to this static event. It fires when an exception in a `Task` goes unobserved (e.g., if a `Task` faults but is never awaited or has no `ContinueWith` handler). This is primarily for *auditing and logging*, not for recovery, as the exception has already occurred and is likely too late to handle gracefully.

**Code Example:**

```csharp
using System;
using System.Threading.Tasks;
using System.Net.Http; // For HttpRequestException

public static class BackgroundTaskMitigation
{
    public static void Run()
    {
        Console.WriteLine("--- Background Task Exception Mitigation ---");

        // Scenario 1: Unhandled exception (bad) - Illustrative only, won't crash in modern .NET
        Console.WriteLine("\nScenario 1: Unhandled in background (will be unobserved, not caught here)");
        StartRiskyBackgroundTask(); // Not awaiting, not catching
        Console.WriteLine("  Risky background task started. Hope it doesn't crash us (it won't, by default in .NET Core+).");

        // Scenario 2: Try-catch within the async lambda (recommended)
        Console.WriteLine("\nScenario 2: Try-catch within async lambda (best practice)");
        StartSafeBackgroundTaskWithTryCatch();
        Console.WriteLine("  Safe background task started with internal try-catch.");

        // Scenario 3: Using ContinueWith (alternative for fire-and-forget logging)
        Console.WriteLine("\nScenario 3: Using ContinueWith(OnlyOnFaulted)");
        StartBackgroundTaskWithContinueWith();
        Console.WriteLine("  Background task started with ContinueWith for fault logging.");

        // Scenario 4: Global UnobservedTaskException handler (for auditing)
        Console.WriteLine("\nScenario 4: Registering Global UnobservedTaskException Handler");
        TaskScheduler.UnobservedTaskException += (sender, args) =>
        {
            Console.WriteLine($"  [GLOBAL HANDLER]: Caught unobserved task exception: {args.Exception.InnerException?.Message ?? args.Exception.Message}");
            args.SetObserved(); // Mark as observed to prevent process termination (historical behavior)
        };
        StartRiskyBackgroundTask(); // Again, this will now be picked up by the global handler
        Console.WriteLine("  Another risky background task started, global handler active.");

        // Give tasks time to complete
        Task.Delay(500).Wait();
        Console.WriteLine("--- End of Background Task Mitigation Demo ---");
    }

    private static void StartRiskyBackgroundTask()
    {
        // This task will throw, and if not awaited/handled, its exception becomes unobserved.
        Task.Run(async () =>
        {
            Console.WriteLine("    [Risky Task]: Starting...");
            await Task.Delay(100);
            throw new InvalidOperationException("Exception from risky background task!");
        });
    }

    private static void StartSafeBackgroundTaskWithTryCatch()
    {
        Task.Run(async () =>
        {
            try
            {
                Console.WriteLine("    [Safe Task]: Starting...");
                await Task.Delay(100);
                throw new HttpRequestException("Exception from safe background task!");
            }
            catch (Exception ex)
            {
                // This exception is handled within the task itself, preventing it from becoming unobserved.
                Console.WriteLine($"    [Safe Task Handler]: Caught exception: {ex.GetType().Name} - {ex.Message}");
                // Log it to your application's logging system
            }
        });
    }

    private static void StartBackgroundTaskWithContinueWith()
    {
        Task.Run(async () =>
        {
            Console.WriteLine("    [ContinueWith Task]: Starting...");
            await Task.Delay(100);
            throw new InvalidOperationException("Exception from ContinueWith task!");
        })
        .ContinueWith(t =>
        {
            if (t.IsFaulted)
            {
                // Accessing t.Exception makes the exception "observed".
                Console.WriteLine($"    [ContinueWith Handler]: Task faulted with: {t.Exception.InnerException?.Message ?? t.Exception.Message}");
                // Log t.Exception for full details
            }
        }, TaskContinuationOptions.OnlyOnFaulted); // Only execute this continuation if the task faulted
    }
}
```

-----

### ðŸ”¹ You implemented `IDisposable` but forgot to call `Dispose()`. How can you ensure cleanup still happens eventually?

(Use a finalizer (`~ClassName`) as a safety net, though not deterministic.)

**Explanation:**

The primary and recommended way to ensure proper resource cleanup for `IDisposable` objects is to explicitly call `Dispose()` (preferably via a `using` statement). However, developers can forget.

To act as a **safety net** or **last resort** for unmanaged resources, you can implement a **finalizer** (also known as a destructor in C++ context).

**How it works:**

  * When an object with a finalizer becomes eligible for garbage collection (i.e., no longer reachable from application roots), the Garbage Collector (GC) doesn't immediately reclaim its memory.
  * Instead, it places the object on a "finalization queue."
  * A dedicated finalizer thread later processes this queue, calling the finalizer method (`~ClassName()`) on each object.
  * After the finalizer runs, the object is then eligible for a subsequent GC collection cycle, where its memory is finally reclaimed.

**Important Considerations:**

  * **Non-deterministic:** You cannot control *when* the finalizer runs. It could be seconds, minutes, or even longer after the object is no longer used, potentially leading to prolonged resource holding.
  * **Performance Overhead:** Objects with finalizers are more expensive for the GC to collect because they require at least two collection cycles.
  * **Only for Unmanaged Resources:** Finalizers should *only* be used for directly held unmanaged resources (like raw pointers, native handles). They are **not** for managed resources (e.g., `Stream`, `SqlConnection`) because those resources already implement `IDisposable` and will clean themselves up through their own finalizers if `Dispose()` isn't called explicitly.
  * **No Exceptions:** As mentioned previously, an unhandled exception escaping a finalizer will typically terminate the process.

**Typical `IDisposable` and Finalizer Pattern (`Dispose` Pattern):**

The standard pattern for classes that own unmanaged resources is to implement both `IDisposable` and a finalizer:

```csharp
using System;

public class MyResourceUser : IDisposable
{
    private bool _isDisposed = false;
    private IntPtr _nativeResourceHandle; // Simulate an unmanaged resource

    public MyResourceUser()
    {
        // Acquire unmanaged resource
        _nativeResourceHandle = new IntPtr(new Random().Next(1000, 9999));
        Console.WriteLine($"  [MyResourceUser]: Acquired native resource: {_nativeResourceHandle}");
    }

    // Public Dispose method for deterministic cleanup
    public void Dispose()
    {
        // Call the private Dispose method and suppress finalization
        Dispose(true);
        GC.SuppressFinalize(this); // Crucial: Prevents the finalizer from running
    }

    // Protected virtual Dispose method for common cleanup logic
    protected virtual void Dispose(bool disposing)
    {
        if (_isDisposed) return;

        if (disposing)
        {
            // Dispose managed resources here
            Console.WriteLine("    Disposing managed resources (if any).");
            // Example: If this class wrapped another IDisposable, dispose it here
            // _anotherDisposableObject.Dispose();
        }

        // Release unmanaged resources here
        if (_nativeResourceHandle != IntPtr.Zero)
        {
            Console.WriteLine($"    Releasing native resource: {_nativeResourceHandle}");
            // Call native methods to release the handle
            // NativeMethods.ReleaseHandle(_nativeResourceHandle);
            _nativeResourceHandle = IntPtr.Zero;
        }

        _isDisposed = true;
    }

    // Finalizer (destructor) - The safety net for unmanaged resources
    ~MyResourceUser()
    {
        Console.WriteLine($"  [MyResourceUser]: Finalizer running for handle: {_nativeResourceHandle} (Dispose() was not called).");
        try
        {
            // Only release unmanaged resources here (disposing is false)
            Dispose(false);
        }
        catch (Exception ex)
        {
            // Crucial: Log but DO NOT re-throw from a finalizer!
            Console.Error.WriteLine($"  [Finalizer Error]: Exception in finalizer for handle {_nativeResourceHandle}: {ex.Message}");
        }
    }
}

public static class FinalizerSafetyNet
{
    public static void Run()
    {
        Console.WriteLine("--- Finalizer as Safety Net ---");

        // Scenario 1: Object created and explicitly disposed (correct usage)
        Console.WriteLine("\nScenario 1: Explicit Dispose() called (finalizer suppressed)");
        using (var resource = new MyResourceUser())
        {
            Console.WriteLine("  Working with MyResourceUser in using block...");
        } // Dispose() is called here
        Console.WriteLine("  Resource explicitly disposed. Finalizer should not run for this instance.");

        // Scenario 2: Object created but Dispose() is forgotten
        Console.WriteLine("\nScenario 2: Dispose() is forgotten (relying on finalizer)");
        CreateAndForgetResource();
        Console.WriteLine("  Resource created and forgotten. Forcing GC to demonstrate finalizer (non-deterministic in real apps)...");

        // Force GC to demonstrate finalizer (DO NOT do this in production normally)
        GC.Collect();
        GC.WaitForPendingFinalizers(); // Wait for finalizers to complete
        GC.Collect(); // Second GC pass to collect finalized objects

        Console.WriteLine("  GC run. Finalizer for the forgotten resource should have executed.");

        Console.WriteLine();
    }

    private static void CreateAndForgetResource()
    {
        var resource = new MyResourceUser();
        // Forget to call resource.Dispose();
        Console.WriteLine("  'MyResourceUser' instance created and then goes out of scope.");
    }
}
```

-----

### ðŸ”¹ You catch an exception in `catch`, dispose a stream manually, and then rethrow. Sometimes the app still leaks handles. Why?

(If `Dispose()` throws its own exception, it masks the original â€” fix by wrapping disposal in `try` or using `using`.)

**Explanation:**

This is a classic problem that highlights the importance of the `using` statement or careful `try-finally` blocks.

Consider this problematic pattern:

```csharp
FileStream stream = null;
try
{
    stream = new FileStream("file.txt", FileMode.Open);
    // ... potentially throw ExceptionA here ...
}
catch (ExceptionA exA) // Catching the specific application exception
{
    // Log ExceptionA
    try
    {
        // PROBLEM: If stream.Dispose() itself throws ExceptionB
        // ExceptionA is now silently swallowed and lost!
        // And ExceptionB is thrown, potentially causing the "leak" if not caught.
        stream?.Dispose();
    }
    catch (ExceptionB exB)
    {
        // This catch block would log ExceptionB, but ExceptionA is gone.
        Console.WriteLine($"Error during dispose: {exB.Message}");
    }
    finally
    {
        throw; // Re-throwing original ExceptionA (but it might be ExceptionB if Dispose threw)
    }
}
```

**What goes wrong:**

1.  An `ExceptionA` occurs within the `try` block.
2.  The `catch (ExceptionA exA)` block is entered.
3.  Inside the `catch` block, you attempt to `stream?.Dispose()`.
4.  **Crucially, `Dispose()` methods themselves *can* throw exceptions** (e.g., if the underlying OS handle is already invalid, or if there's an internal error in the `Dispose` implementation). Let's call this `ExceptionB`.
5.  If `stream.Dispose()` throws `ExceptionB`, then `ExceptionA` (the original, more relevant application exception) is immediately **masked** and effectively lost. The current exception becomes `ExceptionB`.
6.  When you then `throw;`, you are no longer re-throwing `ExceptionA`. You are re-throwing `ExceptionB`.
7.  The original context of `ExceptionA` (which likely caused the main problem) is lost, making debugging much harder. And `ExceptionB` itself might not be caught further up, leading to the "leak" (resource not fully released because `Dispose` failed) or an unexpected crash.

**The Fix:**

The simplest and most robust fix is to use the `using` statement. The C\# compiler translates `using` into a `try-finally` block where the `Dispose()` call is placed in the `finally` block, and importantly, it handles the complexities of exceptions in `finally` blocks in a safe way. If `Dispose()` throws within a `finally`, that `Dispose()` exception *doesn't* mask the original exception from the `try` block; the original exception continues to propagate.

If you *must* dispose manually (e.g., you acquired the resource conditionally or it has a lifetime longer than a single method scope), then wrap the `Dispose()` call itself in its *own* `try-catch` block **within the `finally` block**, ensuring you only log the `Dispose()` exception and still re-throw the *original* exception.

**Code Example:**

```csharp
using System;
using System.IO;

public static class DisposeExceptionMasking
{
    public static void Run()
    {
        Console.WriteLine("--- Dispose() Exception Masking ---");

        // Scenario 1: PROBLEM - Dispose() exception masks original
        Console.WriteLine("\nScenario 1: PROBLEM - Dispose() exception masks original.");
        try
        {
            // Simulate a stream that will throw on dispose
            var disposableThatThrows = new DisposeThrowingStream();
            try
            {
                Console.WriteLine("  Attempting operation...");
                // Simulate application logic throwing
                throw new InvalidOperationException("Original Application Error!");
            }
            catch (InvalidOperationException appEx) // Caught original app error
            {
                Console.WriteLine($"  [Catch]: Caught original app exception: {appEx.Message}");
                try
                {
                    Console.WriteLine("  [Catch]: Attempting to dispose resource...");
                    disposableThatThrows.Dispose(); // This will throw its own exception
                }
                catch (Exception disposeEx) // This catches the Dispose() exception
                {
                    Console.WriteLine($"  [Catch]: Caught EXCEPTION DURING DISPOSE: {disposeEx.Message}");
                    // At this point, appEx is gone from the current exception context!
                    // If we just rethrow, we rethrow disposeEx, not appEx.
                }
                finally
                {
                    // If disposeEx was caught, this 'throw;' rethrows disposeEx.
                    // If disposeEx wasn't caught, this 'throw;' rethrows disposeEx.
                    // The original appEx is GONE from the call stack unless stored.
                    throw; // This is the problematic rethrow point
                }
            }
        }
        catch (Exception finalEx)
        {
            Console.WriteLine($"  [Top-level Catch]: Finally caught: {finalEx.Message}");
            Console.WriteLine($"  Type: {finalEx.GetType().Name}"); // Notice this will be "InvalidOperationException"
                                                                  // if original was IOE and dispose was IOE
                                                                  // but the *instance* is the dispose exception.
                                                                  // For demo, if dispose throws a different type:
                                                                  // if (finalEx is IOException) Console.WriteLine("  This is the dispose error, not the original app error!");
        }

        // Scenario 2: CORRECT - Using 'using' statement
        Console.WriteLine("\nScenario 2: CORRECT - Using 'using' statement (recommended).");
        try
        {
            using (var disposableThatThrows = new DisposeThrowingStream()) // 'using' handles the dispose safely
            {
                Console.WriteLine("  Attempting operation inside using block...");
                throw new InvalidOperationException("Original Application Error!"); // Original app error
            } // Dispose() is called here
        }
        catch (InvalidOperationException appEx) // This will catch the *original* app exception
        {
            Console.WriteLine($"  [Top-level Catch]: Successfully caught ORIGINAL app exception: {appEx.Message}");
            Console.WriteLine($"  Type: {appEx.GetType().Name}");
            // If DisposeThrowingStream.Dispose() threw, that exception would be suppressed
            // by the runtime or added as a suppressed exception in .NET 4.5+ for consistency.
            // The *original* exception is prioritized.
        }
        catch (Exception ex)
        {
            Console.WriteLine($"  [Top-level Catch]: Caught unexpected exception: {ex.Message}");
        }

        Console.WriteLine();
    }
}

// Helper class to simulate a disposable that throws on Dispose()
public class DisposeThrowingStream : IDisposable
{
    private bool _isDisposed = false;
    public DisposeThrowingStream()
    {
        Console.WriteLine("    [DisposeThrowingStream]: Instance created.");
    }

    public void Dispose()
    {
        if (_isDisposed) return;
        _isDisposed = true;
        Console.WriteLine("    [DisposeThrowingStream]: Dispose() called. NOW THROWING DURING DISPOSE!");
        throw new IOException("Simulated error during stream disposal!");
    }
}
```

**Key Lesson:**

Always use `using` statements for `IDisposable` objects whenever possible. If manual disposal is necessary, place the `Dispose()` call within a `finally` block, and wrap the `Dispose()` call itself in its *own* `try-catch` to log any disposal-specific errors without masking the original exception that caused the block to be entered.