It's Sunday, June 22, 2025 at 12:26:00 PM IST in Noida, Uttar Pradesh, India. Let's delve deeply into how to handle exception aggregation when multiple tasks fail in parallel within .NET, focusing on the `AggregateException` and best practices for managing multiple errors.

-----

## How Do You Handle Exception Aggregation When Multiple Tasks Fail in Parallel?

When you execute multiple tasks in parallel using constructs like `Task.WhenAll()`, `Parallel.ForEach()`, or even by manually starting several `Task` objects, it's highly probable that more than one of these tasks might fail. In such scenarios, .NET's Task Parallel Library (TPL) uses a specialized exception type called **`System.AggregateException`** to consolidate all the individual exceptions into a single, comprehensive exception.

The purpose of `AggregateException` is crucial: if any task fails, you don't want to lose information about other tasks that might have also failed. `AggregateException` acts as a container for one or more `InnerException` objects, each representing an exception from a failed task.

### The Role of `AggregateException`

  * **Container for Multiple Exceptions:** Its primary purpose is to hold one or more exceptions that occurred during the execution of a set of tasks.
  * **Flattening:** It has a `Flatten()` method that can be useful if you have nested `AggregateException`s (e.g., if a task that throws an `AggregateException` is itself awaited by another `Task.WhenAll`).
  * **Handling:** You typically iterate through its `InnerExceptions` collection to inspect and handle each individual error.

### How `AggregateException` is Thrown

  * **`Task.WhenAll()`:** If any of the `Task` objects passed to `Task.WhenAll()` faults (throws an unhandled exception) or is canceled, `Task.WhenAll()` will throw an `AggregateException` when it's `awaited` or `.Result`/`.Wait()` is called on it. If multiple tasks fail, all their exceptions will be packaged into the `AggregateException`.
  * **`Parallel.ForEach()` / `Parallel.For()`:** If an unhandled exception occurs during the execution of an iteration within a `Parallel.ForEach` or `Parallel.For` loop, the `Parallel` method will eventually throw an `AggregateException` containing all the exceptions from the failed iterations.
  * **`Task.WaitAll()`:** Similar to `Task.WhenAll()`, the synchronous `Task.WaitAll()` method will throw an `AggregateException` if any of the waited tasks fail.
  * **`Task.Exception` Property:** The `Exception` property of a `Task` that has faulted will return an `AggregateException` containing the original exception(s) that caused the task to fault.

### Handling Strategies with Code Examples

Let's illustrate different ways to handle `AggregateException` when multiple tasks fail.

#### Example 1: Basic `Task.WhenAll()` with `AggregateException` Catch

This is the most common scenario: you `await` `Task.WhenAll()`, and one or more tasks within it fail.

```csharp
using System;
using System.Collections.Generic;
using System.Linq;
using System.Threading.Tasks;

public class TaskWhenAllExceptionHandling
{
    // Simulates a task that might succeed or fail
    private static async Task<string> SimulateWorkAsync(string name, bool shouldFail, int delayMs)
    {
        Console.WriteLine($"  [Task {name}] Starting (delay: {delayMs}ms, fail: {shouldFail})");
        await Task.Delay(delayMs); // Simulate work

        if (shouldFail)
        {
            Console.WriteLine($"  [Task {name}] Intentionally failing!");
            throw new InvalidOperationException($"Task {name} failed as requested.");
        }

        Console.WriteLine($"  [Task {name}] Completed successfully.");
        return $"Result from {name}";
    }

    public static async Task Main(string[] args)
    {
        Console.WriteLine("--- Task.WhenAll() Exception Handling Demo ---");

        List<Task<string>> tasks = new List<Task<string>>
        {
            SimulateWorkAsync("TaskA", false, 500),  // Succeed
            SimulateWorkAsync("TaskB", true, 200),   // Fail quickly
            SimulateWorkAsync("TaskC", false, 700),  // Succeed
            SimulateWorkAsync("TaskD", true, 300),   // Fail
            SimulateWorkAsync("TaskE", false, 400),  // Succeed
            SimulateWorkAsync("TaskF", true, 600)    // Fail
        };

        try
        {
            Console.WriteLine("\nWaiting for all tasks to complete...");
            // Await Task.WhenAll. If any task fails, this line will throw an AggregateException.
            string[] results = await Task.WhenAll(tasks);

            Console.ForegroundColor = ConsoleColor.Green;
            Console.WriteLine("\nAll tasks completed successfully!");
            foreach (var result in results)
            {
                Console.WriteLine($"- {result}");
            }
            Console.ResetColor();
        }
        catch (AggregateException ae)
        {
            Console.ForegroundColor = ConsoleColor.Red;
            Console.WriteLine("\nCaught an AggregateException! One or more tasks failed:");
            // Iterate through the InnerExceptions collection
            foreach (var ex in ae.InnerExceptions)
            {
                Console.WriteLine($"- {ex.GetType().Name}: {ex.Message}");
            }
            Console.ResetColor();
        }
        catch (Exception ex)
        {
            Console.ForegroundColor = ConsoleColor.Red;
            Console.WriteLine($"\nCaught an unexpected general exception: {ex.GetType().Name}: {ex.Message}");
            Console.ResetColor();
        }

        Console.WriteLine("\n--- Task.WhenAll() Exception Handling Demo Finished ---");
    }
}
```

**Expected Output:**

```
--- Task.WhenAll() Exception Handling Demo ---
  [TaskA] Starting (delay: 500ms, fail: False)
  [TaskB] Starting (delay: 200ms, fail: True)
  [TaskC] Starting (delay: 700ms, fail: False)
  [TaskD] Starting (delay: 300ms, fail: True)
  [TaskE] Starting (delay: 400ms, fail: False)
  [TaskF] Starting (delay: 600ms, fail: True)

Waiting for all tasks to complete...
  [TaskB] Intentionally failing!
  [TaskB] Completed successfully. // This line is not reached if exception is thrown.
  [TaskD] Intentionally failing!
  [TaskD] Completed successfully. // This line is not reached if exception is thrown.
  [TaskE] Completed successfully.
  [TaskA] Completed successfully.
  [TaskF] Intentionally failing!
  [TaskF] Completed successfully. // This line is not reached if exception is thrown.
  [TaskC] Completed successfully.

Caught an AggregateException! One or more tasks failed:
- InvalidOperationException: Task B failed as requested.
- InvalidOperationException: Task D failed as requested.
- InvalidOperationException: Task F failed as requested.

--- Task.WhenAll() Exception Handling Demo Finished ---
```

Note that the `Console.WriteLine("... Completed successfully.")` line for failing tasks will not be hit, as the `throw` statement immediately exits the task. All exceptions are collected and presented in the `AggregateException`.

#### Example 2: Handling Specific Exceptions within `AggregateException` using `Handle()`

The `AggregateException.Handle()` method is a powerful way to process exceptions within the `AggregateException` and specify which ones are "handled" (meaning they don't cause the `AggregateException` to be re-thrown).

```csharp
using System;
using System.Collections.Generic;
using System.IO;
using System.Linq;
using System.Threading.Tasks;

public class AggregateExceptionHandleDemo
{
    // Simulates a task that can throw different types of exceptions
    private static async Task SimulateSpecificFailureAsync(string name, int failureType, int delayMs)
    {
        Console.WriteLine($"  [Task {name}] Starting (delay: {delayMs}ms, failure type: {failureType})");
        await Task.Delay(delayMs);

        switch (failureType)
        {
            case 1:
                Console.WriteLine($"  [Task {name}] Throwing InvalidOperationException.");
                throw new InvalidOperationException($"Operation '{name}' is invalid.");
            case 2:
                Console.WriteLine($"  [Task {name}] Throwing UnauthorizedAccessException.");
                throw new UnauthorizedAccessException($"Access denied for '{name}'.");
            case 3:
                Console.WriteLine($"  [Task {name}] Throwing FileNotFoundException.");
                throw new FileNotFoundException($"File for '{name}' not found.");
            default:
                Console.WriteLine($"  [Task {name}] Completed successfully.");
                return;
        }
    }

    public static async Task Main(string[] args)
    {
        Console.WriteLine("--- AggregateException.Handle() Demo ---");

        List<Task> tasks = new List<Task>
        {
            SimulateSpecificFailureAsync("Task1", 0, 500), // Succeed
            SimulateSpecificFailureAsync("Task2", 1, 200), // InvalidOperationException
            SimulateSpecificFailureAsync("Task3", 0, 700), // Succeed
            SimulateSpecificFailureAsync("Task4", 2, 300), // UnauthorizedAccessException
            SimulateSpecificFailureAsync("Task5", 0, 400), // Succeed
            SimulateSpecificFailureAsync("Task6", 3, 600)  // FileNotFoundException
        };

        try
        {
            Console.WriteLine("\nWaiting for tasks to complete, handling specific exceptions...");
            await Task.WhenAll(tasks);
            Console.ForegroundColor = ConsoleColor.Green;
            Console.WriteLine("\nAll tasks completed successfully or handled gracefully.");
            Console.ResetColor();
        }
        catch (AggregateException ae)
        {
            Console.ForegroundColor = ConsoleColor.Red;
            Console.WriteLine("\nCaught an AggregateException. Processing inner exceptions:");

            // Use Handle() to filter and process exceptions.
            // If Handle() returns false for any exception, that exception (or a new AggregateException
            // containing only the unhandled ones) will be re-thrown.
            ae.Handle(ex =>
            {
                if (ex is InvalidOperationException)
                {
                    Console.WriteLine($"- Handled InvalidOperationException: {ex.Message}");
                    return true; // Mark as handled
                }
                else if (ex is UnauthorizedAccessException)
                {
                    Console.WriteLine($"- Handled UnauthorizedAccessException: {ex.Message}");
                    // Log to security audit
                    return true; // Mark as handled
                }
                else
                {
                    // For all other exception types, we let them propagate.
                    Console.WriteLine($"- UNHANDLED Exception: {ex.GetType().Name}: {ex.Message}");
                    return false; // Mark as unhandled, causing the AggregateException to be re-thrown (with only unhandled ones)
                }
            });
            // If any exception was unhandled (returned false from Handle()),
            // then the AggregateException (or a new one containing only unhandled) will re-throw here.
            // In this specific example, since all are handled, the catch block finishes.
            Console.ResetColor();
        }
        catch (Exception ex)
        {
            Console.ForegroundColor = ConsoleColor.Red;
            Console.WriteLine($"\nCaught a leftover general exception (should not happen if Handle() worked correctly): {ex.GetType().Name}: {ex.Message}");
            Console.ResetColor();
        }

        Console.WriteLine("\n--- AggregateException.Handle() Demo Finished ---");
    }
}
```

**Expected Output (where all specific exceptions are handled):**

```
--- AggregateException.Handle() Demo ---
  [Task1] Starting (delay: 500ms, failure type: 0)
  [Task2] Starting (delay: 200ms, failure type: 1)
  [Task3] Starting (delay: 700ms, failure type: 0)
  [Task4] Starting (delay: 300ms, failure type: 2)
  [Task5] Starting (delay: 400ms, failure type: 0)
  [Task6] Starting (delay: 600ms, failure type: 3)

Waiting for tasks to complete, handling specific exceptions...
  [Task2] Throwing InvalidOperationException.
  [Task4] Throwing UnauthorizedAccessException.
  [Task5] Completed successfully.
  [Task1] Completed successfully.
  [Task6] Throwing FileNotFoundException.
  [Task3] Completed successfully.

Caught an AggregateException. Processing inner exceptions:
- Handled InvalidOperationException: Operation 'Task2' is invalid.
- Handled UnauthorizedAccessException: Access denied for 'Task4'.
- UNHANDLED Exception: FileNotFoundException: File for 'Task6' not found. // This one was explicitly unhandled!

Caught a leftover general exception (should not happen if Handle() worked correctly): AggregateException: One or more errors occurred. (File for 'Task6' not found.)

--- AggregateException.Handle() Demo Finished ---
```

Notice that even though `Handle()` processed `FileNotFoundException`, because `return false;` was specified for that type, the `AggregateException` was re-thrown, and the outer `catch (Exception ex)` caught it. This is how `Handle()` allows you to selectively re-throw unhandled exceptions.

#### Example 3: Handling Errors within Individual Tasks (Partial Success)

Sometimes, you want to collect all results, even if some tasks failed. You don't want `Task.WhenAll()` to throw an `AggregateException` and stop your processing. In this case, you can "swallow" the exception within each individual task using a `try-catch` block inside the `async` method, and then return a custom result object that indicates success or failure.

```csharp
using System;
using System.Collections.Generic;
using System.Linq;
using System.Threading.Tasks;

public class PartialSuccessDemo
{
    public class TaskResult
    {
        public string Name { get; set; }
        public bool IsSuccess { get; set; }
        public string Data { get; set; }
        public Exception Error { get; set; }
    }

    // Simulates a task that might succeed or fail, returning a custom result object
    private static async Task<TaskResult> SimulateWorkAndReturnResultAsync(string name, bool shouldFail, int delayMs)
    {
        try
        {
            Console.WriteLine($"  [Task {name}] Starting (delay: {delayMs}ms, fail: {shouldFail})");
            await Task.Delay(delayMs);

            if (shouldFail)
            {
                Console.WriteLine($"  [Task {name}] Intentionally failing!");
                throw new InvalidOperationException($"Task {name} failed internally.");
            }

            Console.WriteLine($"  [Task {name}] Completed successfully.");
            return new TaskResult { Name = name, IsSuccess = true, Data = $"Result from {name}" };
        }
        catch (Exception ex)
        {
            Console.WriteLine($"  [Task {name}] Caught internal error: {ex.Message}");
            return new TaskResult { Name = name, IsSuccess = false, Error = ex };
        }
    }

    public static async Task Main(string[] args)
    {
        Console.WriteLine("--- Partial Success Demo ---");

        List<Task<TaskResult>> tasks = new List<Task<TaskResult>>
        {
            SimulateWorkAndReturnResultAsync("TaskA", false, 500),
            SimulateWorkAndReturnResultAsync("TaskB", true, 200),
            SimulateWorkAndReturnResultAsync("TaskC", false, 700),
            SimulateWorkAndReturnResultAsync("TaskD", true, 300),
            SimulateWorkAndReturnResultAsync("TaskE", false, 400),
            SimulateWorkAndReturnResultAsync("TaskF", true, 600)
        };

        try
        {
            Console.WriteLine("\nWaiting for all tasks to complete (including failed ones)...");
            // Await Task.WhenAll. It won't throw an AggregateException because individual tasks handle their errors.
            TaskResult[] allResults = await Task.WhenAll(tasks);

            Console.WriteLine("\n--- All Task Results ---");
            foreach (var result in allResults.OrderBy(r => r.Name)) // Order for consistent output
            {
                if (result.IsSuccess)
                {
                    Console.ForegroundColor = ConsoleColor.Green;
                    Console.WriteLine($"[SUCCESS] {result.Name}: {result.Data}");
                }
                else
                {
                    Console.ForegroundColor = ConsoleColor.Red;
                    Console.WriteLine($"[FAILED] {result.Name}: {result.Error.Message}");
                }
                Console.ResetColor();
            }
        }
        catch (Exception ex)
        {
            // This catch block should ideally not be hit if all internal errors are handled.
            Console.ForegroundColor = ConsoleColor.Red;
            Console.WriteLine($"\nCaught an unexpected general exception (should not happen): {ex.GetType().Name}: {ex.Message}");
            Console.ResetColor();
        }

        Console.WriteLine("\n--- Partial Success Demo Finished ---");
    }
}
```

**Expected Output:**

```
--- Partial Success Demo ---
  [TaskA] Starting (delay: 500ms, fail: False)
  [TaskB] Starting (delay: 200ms, fail: True)
  [TaskC] Starting (delay: 700ms, fail: False)
  [TaskD] Starting (delay: 300ms, fail: True)
  [TaskE] Starting (delay: 400ms, fail: False)
  [TaskF] Starting (delay: 600ms, fail: True)

Waiting for all tasks to complete (including failed ones)...
  [TaskB] Intentionally failing!
  [TaskB] Caught internal error: Task B failed internally.
  [TaskD] Intentionally failing!
  [TaskD] Caught internal error: Task D failed internally.
  [TaskE] Completed successfully.
  [TaskA] Completed successfully.
  [TaskF] Intentionally failing!
  [TaskF] Caught internal error: Task F failed internally.
  [TaskC] Completed successfully.

--- All Task Results ---
[SUCCESS] TaskA: Result from TaskA
[FAILED] TaskB: Task B failed internally.
[SUCCESS] TaskC: Result from TaskC
[FAILED] TaskD: Task D failed internally.
[SUCCESS] TaskE: Result from TaskE
[FAILED] TaskF: Task F failed internally.

--- Partial Success Demo Finished ---
```

This pattern is useful when you need to perform actions on all results, regardless of individual task success or failure (e.g., displaying a report of all operations).

### Best Practices for Exception Handling in Parallel Tasks:

1.  **Prefer `async`/`await`:** Use `async` methods and `await Task.WhenAll()` for I/O-bound parallel operations.
2.  **Anticipate `AggregateException`:** Always `catch (AggregateException ae)` when using `Task.WhenAll()`, `Parallel.ForEach()`, or other TPL constructs that might aggregate exceptions.
3.  **Iterate `InnerExceptions`:** Access `ae.InnerExceptions` to get all individual exceptions.
4.  **Use `Handle()` for Specific Processing:** If you have different handling logic for various exception types, `ae.Handle()` is excellent. Remember to return `true` if you've fully handled an exception and `false` if you want it to propagate (causing the `AggregateException` to be re-thrown).
5.  **Swallow Internally for Partial Success:** If your application can logically continue even if some parallel operations fail, wrap the core logic of each individual task in a `try-catch` block and return a custom result object that indicates success/failure. This prevents `Task.WhenAll()` from throwing and allows you to collect all outcomes.
6.  **Logging:** Always log the details of aggregated exceptions. `AggregateException` provides a comprehensive view of what went wrong.
7.  **Consider `ExceptionDispatchInfo`:** For more advanced scenarios where you need to re-throw an exception while preserving its original stack trace, `ExceptionDispatchInfo.Capture(ex).Throw();` can be useful, though it's typically for re-throwing from a different context/thread.

By properly handling `AggregateException`, you ensure that your parallel code is robust, resilient, and provides comprehensive error information, making debugging and maintenance much easier.