It's Saturday, June 21, 2025 at 9:50:37 PM IST in Noida, Uttar Pradesh, India. Let's dive deeply into `async void` methods in C\#, explaining their purpose, their significant limitations, and when (and when not) to use them, complete with practical code examples.

-----

## Can You Write an Async Method That Returns `void`? When?

Yes, you absolutely **can** write an `async` method that returns `void` in C\#. It's a special return type for `async` methods, alongside `Task` and `Task<TResult>`.

### The Nature of `async void`

Unlike `async Task` or `async Task<TResult>`, an `async void` method does **not** return an awaitable object. This has a profound implication:

  * **Fire and Forget:** When you call an `async void` method, the caller cannot `await` its completion. The control returns to the caller immediately, and the caller has no direct way to know when the `async void` method finishes its asynchronous operations, nor can it capture any exceptions that occur within it in a conventional `try-catch` block.
  * **Exception Handling:** Exceptions thrown from an `async void` method (and not caught within the method itself) are re-thrown on the `SynchronizationContext` (if one exists) that was active when the `async void` method began. If there's no `SynchronizationContext`, the exception will typically propagate to the `ThreadPool` and crash the application (or cause the `AppDomain.CurrentDomain.UnhandledException` event to fire). This is a major reason why `async void` is generally discouraged.

### When to Use `async void` (The Only Legitimate Scenario)

The **only** legitimate and common scenario for using `async void` is for **event handlers**.

**Why for Event Handlers?**

Event handlers in UI frameworks (like WPF, Windows Forms, Xamarin.Forms, UWP) and older ASP.NET Web Forms are traditionally `void`-returning methods. The event infrastructure doesn't understand `Task` objects; it expects a `void` return. If you need to perform asynchronous operations within an event handler (e.g., fetching data from a web service when a button is clicked), `async void` is the bridge.

In such cases, the UI framework's `SynchronizationContext` (e.g., `DispatcherSynchronizationContext` in WPF) will capture and handle exceptions from the `async void` method, usually by presenting an error dialog or logging it.

**Example: `async void` in a WPF Button Click Event Handler**

Let's illustrate with a simple WPF application (similar to the previous async deadlock example).

**WPF MainWindow.xaml (minimal setup):**

```xml
<Window x:Class="AsyncVoidDemo.MainWindow"
        xmlns="http://schemas.microsoft.com/winfx/2006/xaml/presentation"
        xmlns:x="http://schemas.microsoft.com/winfx/2006/xaml"
        Title="Async Void Demo" Height="200" Width="450">
    <Grid>
        <StackPanel VerticalAlignment="Center" HorizontalAlignment="Center">
            <Button Content="Fetch Data Async" Click="FetchDataButton_Click" Margin="10"/>
            <TextBlock x:Name="StatusTextBlock" Text="Ready" HorizontalAlignment="Center" Margin="10"/>
        </StackPanel>
    </Grid>
</Window>
```

**WPF MainWindow.xaml.cs (using `async void`):**

```csharp
using System;
using System.Net.Http;
using System.Threading;
using System.Threading.Tasks;
using System.Windows;
using System.Windows.Controls;

namespace AsyncVoidDemo
{
    public partial class MainWindow : Window
    {
        private static readonly HttpClient _httpClient = new HttpClient();

        public MainWindow()
        {
            InitializeComponent();
        }

        // --- Legitimate use case: Event handler ---
        private async void FetchDataButton_Click(object sender, RoutedEventArgs e)
        {
            StatusTextBlock.Text = "Fetching data...";
            Console.WriteLine($"[UI Thread {Thread.CurrentThread.ManagedThreadId}] Button Clicked. Starting async operation...");
            
            try
            {
                // The actual async work
                string data = await SimulateNetworkCallAsync();
                
                // This continuation will resume on the UI thread due to the captured SynchronizationContext
                StatusTextBlock.Text = $"Data received: {data.Length} chars.";
                Console.WriteLine($"[UI Thread {Thread.CurrentThread.ManagedThreadId}] Data displayed on UI.");
            }
            catch (Exception ex)
            {
                // All exceptions in an async void method should be caught here!
                StatusTextBlock.Text = $"Error: {ex.Message}";
                Console.WriteLine($"[UI Thread {Thread.CurrentThread.ManagedThreadId}] Caught exception: {ex.Message}");
                MessageBox.Show($"An error occurred: {ex.Message}", "Error", MessageBoxButton.OK, MessageBoxImage.Error);
            }
        }

        private async Task<string> SimulateNetworkCallAsync()
        {
            Console.WriteLine($"  [Thread {Thread.CurrentThread.ManagedThreadId}] Inside SimulateNetworkCallAsync (before await).");
            
            // Simulate a network call with a delay
            await Task.Delay(2000).ConfigureAwait(false); // Use ConfigureAwait(false) for library methods to free up UI thread earlier
            
            Console.WriteLine($"  [Thread {Thread.CurrentThread.ManagedThreadId}] Inside SimulateNetworkCallAsync (after await).");

            // Example of a potential error within the async flow
            // throw new InvalidOperationException("Simulated network error!"); 

            return "This is some data fetched from a simulated network source.";
        }
    }
}
```

**How it works in the example:**

1.  When the button is clicked, `FetchDataButton_Click` (an `async void` method) is invoked.
2.  `StatusTextBlock` is updated, and `SimulateNetworkCallAsync()` is called.
3.  `SimulateNetworkCallAsync()` performs an `await Task.Delay(2000).ConfigureAwait(false);`. The `ConfigureAwait(false)` means the continuation of `SimulateNetworkCallAsync` might run on a `ThreadPool` thread.
4.  Control immediately returns to `FetchDataButton_Click`. Since it `awaited` `SimulateNetworkCallAsync()`, `FetchDataButton_Click` itself *suspends* and returns control to the WPF event loop. This keeps the UI responsive.
5.  After 2 seconds, `SimulateNetworkCallAsync()` completes, and its result is passed back to `FetchDataButton_Click`.
6.  The continuation of `FetchDataButton_Click` (the code after `await SimulateNetworkCallAsync()`) is marshaled back to the UI thread (because `FetchDataButton_Click` is an `async void` method initiated from the UI thread, and it implicitly uses `ConfigureAwait(true)` for its own continuation).
7.  `StatusTextBlock` is updated, and the operation is complete.

**Exception Handling in `async void`:**

If you uncomment `throw new InvalidOperationException("Simulated network error!");` inside `SimulateNetworkCallAsync()`, the `catch (Exception ex)` block within `FetchDataButton_Click` will successfully capture the exception, preventing the application from crashing. This is because the UI framework's `SynchronizationContext` catches such exceptions and dispatches them to the `AppDomain.CurrentDomain.UnhandledException` event *if they are not handled within the `async void` method itself*. By putting a `try-catch` directly inside the `async void` method, you ensure local handling.

### When **NOT** to Use `async void` (Almost Always\!)

Outside of event handlers, `async void` is almost always a bad idea due to the "fire and forget" nature and the poor exception handling model.

**Problems with `async void` in non-event-handler contexts:**

1.  **Uncatchable Exceptions (from the caller's perspective):** If an `async void` method throws an unhandled exception, it's not propagated back to the caller in a `Task` that can be awaited. Instead, it's re-thrown on the `SynchronizationContext` or the `ThreadPool`, often leading to an application crash (unhandled exception).

      * **Code Example 1: Unhandled Exception in `async void` (Console App)**
        ```csharp
        using System;
        using System.Threading.Tasks;

        public class AsyncVoidBadPractice
        {
            public static async Task Main(string[] args)
            {
                Console.WriteLine("--- Async Void Bad Practice Demo ---");

                try
                {
                    Console.WriteLine("Calling PerformActionAsyncVoid - expecting unhandled exception...");
                    PerformActionAsyncVoid(); // Cannot await this!
                    Console.WriteLine("Main method continues immediately after calling async void.");
                }
                catch (Exception ex)
                {
                    // This catch block WILL NOT catch exceptions from PerformActionAsyncVoid!
                    Console.ForegroundColor = ConsoleColor.Red;
                    Console.WriteLine($"Caught exception in Main: {ex.Message}");
                    Console.ResetColor();
                }

                // Give some time for the async void method to execute and potentially crash
                await Task.Delay(2000); 

                Console.WriteLine("\n--- Async Void Bad Practice Demo Finished (if not crashed) ---");
            }

            private static async void PerformActionAsyncVoid()
            {
                Console.WriteLine($"  [Thread {System.Threading.Thread.CurrentThread.ManagedThreadId}] PerformActionAsyncVoid: Starting...");
                await Task.Delay(500);
                Console.WriteLine($"  [Thread {System.Threading.Thread.CurrentThread.ManagedThreadId}] PerformActionAsyncVoid: About to throw exception.");
                throw new InvalidOperationException("Something went wrong in async void!"); // Unhandled exception
            }
        }
        ```
        **Output (`AsyncVoidBadPractice`):**
        ```
        --- Async Void Bad Practice Demo ---
        Calling PerformActionAsyncVoid - expecting unhandled exception...
        Main method continues immediately after calling async void.
          [Thread 3] PerformActionAsyncVoid: Starting...
        [Wait 500ms]
          [Thread 3] PerformActionAsyncVoid: About to throw exception.

        Unhandled exception. System.InvalidOperationException: Something went wrong in async void!
           at AsyncVoidBadPractice.PerformActionAsyncVoid() in C:\...\AsyncVoidBadPractice.cs:line 30
        // Application terminates
        ```
        The application crashes because the exception from `PerformActionAsyncVoid` is not caught by `Main`'s `try-catch` block.

2.  **No Way to Know Completion:** You can't `await` an `async void` method. This means you can't reliably perform operations *after* it has finished, nor can you integrate it into larger async workflows (e.g., `Task.WhenAll`, `Task.WhenAny`). This makes coordination impossible.

      * **Code Example 2: No Completion Tracking**
        ```csharp
        using System;
        using System.Threading.Tasks;

        public class AsyncVoidNoCompletionDemo
        {
            public static async Task Main(string[] args)
            {
                Console.WriteLine("--- Async Void No Completion Demo ---");

                Console.WriteLine("Starting LongRunningAsyncVoid...");
                LongRunningAsyncVoid(); // Fire and forget
                Console.WriteLine("Main method continues immediately. LongRunningAsyncVoid is running independently.");

                // How do we know when LongRunningAsyncVoid is done? We don't.
                // We'll just wait arbitrarily long here to let it finish.
                await Task.Delay(3000); 

                Console.WriteLine("\n--- Async Void No Completion Demo Finished ---");
            }

            private static async void LongRunningAsyncVoid()
            {
                Console.WriteLine($"  [Thread {System.Threading.Thread.CurrentThread.ManagedThreadId}] LongRunningAsyncVoid: Starting work...");
                await Task.Delay(2000); // Simulate 2 seconds of work
                Console.WriteLine($"  [Thread {System.Threading.Thread.ManagedThreadId}] LongRunningAsyncVoid: Work finished.");
            }
        }
        ```
        **Output (`AsyncVoidNoCompletionDemo`):**
        ```
        --- Async Void No Completion Demo ---
        Starting LongRunningAsyncVoid...
        Main method continues immediately. LongRunningAsyncVoid is running independently.
          [Thread 3] LongRunningAsyncVoid: Starting work...
        [Wait 2 seconds]
          [Thread 3] LongRunningAsyncVoid: Work finished.

        --- Async Void No Completion Demo Finished ---
        ```
        Notice how `Main` finishes its output and `Task.Delay(3000)` only serves to artificially keep the process alive long enough for `LongRunningAsyncVoid` to print its "finished" message. In a real scenario, if `Main` exited without waiting, the `LongRunningAsyncVoid` might be abruptly terminated or its output simply lost.

### The Alternative: `async Task` (Almost Always Preferable)

For almost all scenarios outside of event handlers, an `async` method should return `Task` (if it doesn't produce a result) or `Task<TResult>` (if it produces a result).

**Benefits of `async Task`/`async Task<TResult>`:**

  * **Awaitable:** Callers can `await` the method, knowing when it completes and getting its result (if any).
  * **Propagated Exceptions:** Exceptions thrown from `async Task`/`async Task<TResult>` methods are captured within the returned `Task` object. The caller can then handle these exceptions using a `try-catch` block when `await`ing the `Task`.
  * **Composability:** `Task` objects can be easily combined using `Task.WhenAll`, `Task.WhenAny`, etc., allowing for complex asynchronous workflows.

**Code Example 3: The Better Way - `async Task`**

```csharp
using System;
using System.Threading.Tasks;

public class AsyncTaskGoodPractice
{
    public static async Task Main(string[] args)
    {
        Console.WriteLine("--- Async Task Good Practice Demo ---");

        try
        {
            Console.WriteLine("Calling PerformActionAsyncTask - awaiting for completion and handling potential exceptions...");
            await PerformActionAsyncTask(); // Awaiting the Task, so completion and exceptions are handled.
            Console.WriteLine("PerformActionAsyncTask completed successfully.");
        }
        catch (InvalidOperationException ex)
        {
            // This catch block WILL catch exceptions from PerformActionAsyncTask!
            Console.ForegroundColor = ConsoleColor.Green; // Indicate successful catch
            Console.WriteLine($"Caught expected exception in Main: {ex.Message}");
            Console.ResetColor();
        }
        catch (Exception ex)
        {
            Console.ForegroundColor = ConsoleColor.Red;
            Console.WriteLine($"Caught unexpected exception in Main: {ex.GetType().Name} - {ex.Message}");
            Console.ResetColor();
        }

        Console.WriteLine("\n--- Async Task Good Practice Demo Finished ---");
    }

    // This method returns Task, making it awaitable and its exceptions catchable.
    private static async Task PerformActionAsyncTask()
    {
        Console.WriteLine($"  [Thread {System.Threading.Thread.CurrentThread.ManagedThreadId}] PerformActionAsyncTask: Starting...");
        await Task.Delay(500);
        Console.WriteLine($"  [Thread {System.Threading.Thread.ManagedThreadId}] PerformActionAsyncTask: About to throw exception.");
        throw new InvalidOperationException("Something went wrong in async Task!"); // Exception is captured in the returned Task
    }
}
```

**Output (`AsyncTaskGoodPractice`):**

```
--- Async Task Good Practice Demo ---
Calling PerformActionAsyncTask - awaiting for completion and handling potential exceptions...
  [Thread 3] PerformActionAsyncTask: Starting...
[Wait 500ms]
  [Thread 3] PerformActionAsyncTask: About to throw exception.
Caught expected exception in Main: Something went wrong in async Task!

--- Async Task Good Practice Demo Finished ---
```

Here, the exception from `PerformActionAsyncTask` is properly wrapped in the `Task` it returns, and `Main`'s `await` operation unwraps and re-throws that exception, allowing the `try-catch` block in `Main` to handle it gracefully.

### Summary: `async void` - Use Sparingly

  * **Use `async void` ONLY for event handlers** (UI, old ASP.NET Web Forms) where the framework expects a `void` return type.
  * **In all other scenarios, use `async Task` or `async Task<TResult>`**.
  * **Always include a `try-catch` block** in your `async void` event handlers to ensure exceptions are gracefully handled and don't crash the application.
  * Be aware of the "fire and forget" nature of `async void` and its inability to be awaited or tracked. This makes debugging and coordination much harder.

By adhering to these guidelines, you can leverage the power of asynchronous programming while avoiding the pitfalls associated with `async void`.