It's Saturday, June 21, 2025 at 9:58:34 PM IST in Noida, Uttar Pradesh, India. Let's delve deeply into the consequences of **not `await`ing an `async` method**, exploring the various scenarios and providing clear code examples to illustrate the pitfalls.

-----

## What Happens if You Don't `await` an `async` Method?

When you call an `async` method that returns `Task` or `Task<TResult>`, it immediately begins executing synchronously until it hits its first `await` that resolves to an incomplete task, or until it `return`s. At that point, the `async` method suspends its execution, and a `Task` object representing the ongoing operation is returned to the caller.

If the caller **does not `await` this returned `Task`**, several significant things happen (or, more accurately, *don't* happen) that can lead to subtle bugs, unexpected behavior, and debugging headaches.

### Core Principle: "Fire and Forget" (Without the `async void` Guarantee)

When you call an `async Task` or `async Task<TResult>` method and don't `await` it, you are effectively treating it as a "fire and forget" operation, similar to how `async void` methods behave. However, unlike `async void` (which has very specific, limited use cases), "fire and forget" with `async Task` is generally a strong indication of a mistake unless you're intentionally implementing a background task dispatcher.

### What Happens (or Doesn't Happen):

1.  **No Waiting for Completion:**

      * The most immediate effect: The calling code **does not wait** for the `async` method to complete. It continues executing immediately after the call to the `async` method, concurrently with the `async` method's execution.
      * This can lead to race conditions if the calling code depends on the `async` method's side effects or results.

2.  **Unhandled Exceptions Become Difficult to Trace/Catch:**

      * This is arguably the most dangerous consequence. If the un-awaited `async` method throws an exception, that exception will be stored within the `Task` object it returned.
      * If no code ever `await`s that `Task` (or accesses its `.Result` or `.Exception` property), that exception is considered **unobserved**.
      * In older .NET versions (prior to .NET 4.5 by default, and in .NET 4.5+ if a specific configuration is enabled), an unobserved exception could lead to process termination when the `Task` was garbage collected (though this behavior was changed to be less aggressive by default in .NET 4.5 to avoid surprising crashes).
      * Even if it doesn't crash the app, an unobserved exception will typically not be logged or handled in a conventional `try-catch` block, making debugging extremely difficult. The error might silently occur in the background.

3.  **Return Value is Lost/Ignored:**

      * If it's an `async Task<TResult>` method, the `TResult` value produced by the `async` method will never be consumed by the calling code because there's no `await` to unwrap it.

4.  **Resource Management Issues:**

      * If the un-awaited `async` method is responsible for acquiring and releasing resources (e.g., database connections, file handles), and the calling code assumes those resources are released by the time *it* continues, you could end up with resource leaks or incorrect state.

5.  **Debugging Challenges:**

      * The asynchronous flow becomes much harder to follow. Exceptions occur in the background, making stack traces less useful. Breakpoints might be hit at unexpected times or not at all.

### Code Examples Illustrating the Issues

Let's use a console application for clarity, as it typically doesn't have a `SynchronizationContext` to mask these behaviors.

#### Example 1: No Waiting & Unhandled Exception (Most Common Pitfall)

```csharp
using System;
using System.Threading;
using System.Threading.Tasks;

public class NoAwaitCrashDemo
{
    public static async Task Main(string[] args)
    {
        Console.WriteLine("--- No Await Crash Demo ---");
        Console.WriteLine($"Main thread ID: {Thread.CurrentThread.ManagedThreadId}");

        try
        {
            Console.WriteLine("Calling PerformActionThatMightFailAsync but NOT AWAITING IT...");
            // CRITICAL: Not awaiting the Task returned by this async method
            PerformActionThatMightFailAsync(); 
            
            Console.WriteLine("Main method continues immediately after calling PerformActionThatMightFailAsync.");

            // Give some time for the un-awaited task to potentially run and throw its exception
            Console.WriteLine("Waiting for 2 seconds to see what happens...");
            await Task.Delay(2000); 
            
            Console.WriteLine("\n--- No Await Crash Demo Finished (if not crashed) ---");
        }
        catch (Exception ex)
        {
            // This catch block WILL NOT catch exceptions from PerformActionThatMightFailAsync
            Console.ForegroundColor = ConsoleColor.Red;
            Console.WriteLine($"!!! Caught exception in Main: {ex.Message} (THIS WON'T HAPPEN!)");
            Console.ResetColor();
        }
        
        // In .NET Core, unobserved exceptions from Task don't crash by default.
        // However, they can still be a silent bug.
        // To see crashes in .NET 5+, you might need:
        // TaskScheduler.UnobservedTaskException += (sender, e) => 
        // { 
        //    Console.WriteLine($"UNOBSERVED EXCEPTION: {e.Exception}"); 
        //    e.SetObserved(); // Mark as observed to prevent crash (if default behavior was changed)
        // };
    }

    private static async Task PerformActionThatMightFailAsync()
    {
        Console.WriteLine($"  [Async Method, Thread {Thread.CurrentThread.ManagedThreadId}] PerformActionThatMightFailAsync: Starting...");
        await Task.Delay(500); // Simulate some async work
        
        Console.WriteLine($"  [Async Method, Thread {Thread.CurrentThread.ManagedThreadId}] PerformActionThatMightFailAsync: About to throw an exception.");
        throw new InvalidOperationException("Something went wrong in the un-awaited async method!"); // This exception is "unobserved"
    }
}
```

**Expected Output (`NoAwaitCrashDemo`):**

```
--- No Await Crash Demo ---
Main thread ID: 1
Calling PerformActionThatMightFailAsync but NOT AWAITING IT...
Main method continues immediately after calling PerformActionThatMightFailAsync.
  [Async Method, Thread 3] PerformActionThatMightFailAsync: Starting...
Waiting for 2 seconds to see what happens...
[After 500ms delay]
  [Async Method, Thread 3] PerformActionThatMightFailAsync: About to throw an exception.
[Application then finishes, and you might see an unobserved task exception warning in debug output, but no direct crash from Main's try-catch]

--- No Await Crash Demo Finished (if not crashed) ---
```

**Explanation:** The `InvalidOperationException` is thrown *inside* `PerformActionThatMightFailAsync`, but because `Main` doesn't `await` it, `Main`'s `try-catch` block is oblivious to it. The exception is stored within the `Task` returned by `PerformActionThatMightFailAsync`. If you run this with a debugger attached, you'll likely see a warning about an "unobserved task exception" in the output window. If you're running without a debugger, it might simply pass silently, leading to data corruption or incorrect application state without an obvious error.

#### Example 2: Lost Return Value

If you don't `await` an `async Task<TResult>`, you effectively lose access to `TResult`.

```csharp
using System;
using System.Threading.Tasks;
using System.Threading;

public class NoAwaitLostResultDemo
{
    public static async Task Main(string[] args)
    {
        Console.WriteLine("--- No Await Lost Result Demo ---");

        Console.WriteLine("Calling GetMessageAsync() but NOT AWAITING IT...");
        // Calling an async Task<string> method but not awaiting its Task
        Task<string> messageTask = GetMessageAsync(); 
        
        Console.WriteLine("Main method continues immediately.");

        // We can access the Task object, but its Result is not yet available
        // Attempting to access .Result synchronously here would block,
        // which defeats the purpose of async and can lead to deadlock in UI/ASP.NET.
        // Console.WriteLine($"Attempting to get result synchronously: {messageTask.Result}"); // This would block/deadlock

        Console.WriteLine("Trying to perform other work while message is 'fetching'...");
        await Task.Delay(500); // Simulate other work

        // If we want the result later, we MUST await the Task
        // string finalMessage = await messageTask; // This is the correct way if we need the result eventually
        
        Console.WriteLine("Main method finished, but the async operation might still be running.");

        await Task.Delay(2000); // Ensure GetMessageAsync has time to finish and print its message
        Console.WriteLine("\n--- No Await Lost Result Demo Finished ---");
    }

    private static async Task<string> GetMessageAsync()
    {
        Console.WriteLine($"  [Async Method, Thread {Thread.CurrentThread.ManagedThreadId}] GetMessageAsync: Starting to fetch message...");
        await Task.Delay(1000); // Simulate network call or long computation
        Console.WriteLine($"  [Async Method, Thread {Thread.CurrentThread.ManagedThreadId}] GetMessageAsync: Message fetched.");
        return "Hello from the async world!";
    }
}
```

**Expected Output (`NoAwaitLostResultDemo`):**

```
--- No Await Lost Result Demo ---
Calling GetMessageAsync() but NOT AWAITING IT...
Main method continues immediately.
  [Async Method, Thread 3] GetMessageAsync: Starting to fetch message...
Trying to perform other work while message is 'fetching'...
[After 500ms delay]
Main method finished, but the async operation might still be running.
[After another 1500ms delay]
  [Async Method, Thread 3] GetMessageAsync: Message fetched.

--- No Await Lost Result Demo Finished ---
```

`Main` prints its "finished" message before `GetMessageAsync` has actually completed its work and produced its result. The `string` "Hello from the async world\!" is returned by `GetMessageAsync`, but since `Main` never `await`s `messageTask`, that result is never retrieved or used.

#### Example 3: Race Conditions and Unexpected State

When operations proceed concurrently without proper `await`ing, you can run into race conditions.

```csharp
using System;
using System.Threading.Tasks;
using System.Threading;

public class NoAwaitRaceConditionDemo
{
    private static int _counter = 0;

    public static async Task Main(string[] args)
    {
        Console.WriteLine("--- No Await Race Condition Demo ---");

        Console.WriteLine("Calling IncrementCounterAsync() 3 times without awaiting...");
        // Launching multiple async methods without awaiting them
        IncrementCounterAsync(); 
        IncrementCounterAsync();
        IncrementCounterAsync();

        Console.WriteLine("Main method continues immediately. Counter value might be unexpected.");
        // This will likely print 0 or 1, because the async increments haven't completed yet
        Console.WriteLine($"Current counter value (before waiting): {_counter}"); 

        Console.WriteLine("Waiting for async operations to complete...");
        await Task.Delay(2000); // Give time for the increments to finish

        // Now the counter should reflect all increments
        Console.WriteLine($"Current counter value (after waiting): {_counter}");

        Console.WriteLine("\n--- No Await Race Condition Demo Finished ---");
    }

    private static async Task IncrementCounterAsync()
    {
        Console.WriteLine($"  [Async Method, Thread {Thread.CurrentThread.ManagedThreadId}] IncrementCounterAsync: Starting...");
        await Task.Delay(500); // Simulate some async work
        Interlocked.Increment(ref _counter); // Thread-safe increment
        Console.WriteLine($"  [Async Method, Thread {Thread.CurrentThread.ManagedThreadId}] IncrementCounterAsync: Counter incremented to {_counter}.");
    }
}
```

**Expected Output (`NoAwaitRaceConditionDemo`):**

```
--- No Await Race Condition Demo ---
Calling IncrementCounterAsync() 3 times without awaiting...
  [Async Method, Thread 3] IncrementCounterAsync: Starting...
  [Async Method, Thread 4] IncrementCounterAsync: Starting...
  [Async Method, Thread 5] IncrementCounterAsync: Starting...
Main method continues immediately. Counter value might be unexpected.
Current counter value (before waiting): 0 // Or 1, if one was very quick
Waiting for async operations to complete...
[After 500ms delay]
  [Async Method, Thread 4] IncrementCounterAsync: Counter incremented to 1.
  [Async Method, Thread 5] IncrementCounterAsync: Counter incremented to 2.
  [Async Method, Thread 3] IncrementCounterAsync: Counter incremented to 3.
[After another 1500ms delay]
Current counter value (after waiting): 3

--- No Await Race Condition Demo Finished ---
```

The "Current counter value (before waiting)" is incorrect because the `IncrementCounterAsync` calls haven't finished yet. This highlights that `await` is essential for controlling the flow and ensuring operations complete before their results are needed.

### When is it OK to Not `await` an `async Task`?

There are very few, specific scenarios where explicitly choosing *not* to `await` an `async Task` is acceptable and intentional:

1.  **True Background "Fire and Forget" Tasks:** When you genuinely want to start a task that runs completely independently in the background, without affecting the calling code's flow or requiring its result/exception handling. This is rare in typical application logic but can be useful for logging, analytics, or non-critical cleanup operations that must *not* block the main flow.

      * **Caveat:** Even then, you **must** handle exceptions within the background task itself (e.g., with a `try-catch` inside the `async` method, or by explicitly checking `task.Exception` at some point) to prevent unobserved exceptions.
      * Example: `_ = DoLoggingAsync();` (The `_ =` syntax explicitly discards the `Task` to suppress compiler warnings, indicating intentional "fire and forget").

2.  **`Task.WhenAll` / `Task.WhenAny` Composition:** When you are collecting multiple `Task` objects to then `await` them all together or `await` the first one to complete. Here, you're not `await`ing individual tasks immediately, but you *are* collecting them into a collection and then `await`ing the composite `Task`.

    ```csharp
    List<Task<string>> downloadTasks = new List<Task<string>>();
    downloadTasks.Add(DownloadFileAsync("file1.txt")); // Not awaited here
    downloadTasks.Add(DownloadFileAsync("file2.txt")); // Not awaited here
    downloadTasks.Add(DownloadFileAsync("file3.txt")); // Not awaited here

    // Now, await all of them collectively
    string[] results = await Task.WhenAll(downloadTasks); 
    ```

### Conclusion

In summary, **always `await` an `async` method that returns `Task` or `Task<TResult>` unless you have a very specific, well-understood reason not to.** The `await` keyword is fundamental to proper asynchronous flow control, exception handling, and reliable execution in C\#. Failing to `await` often leads to silent bugs, lost data, and notoriously difficult-to-debug issues.