Let's clarify the critical difference between `throw;` and `throw ex;` in C\# exception handling, a common source of confusion and subtle bugs.

## `throw` vs. `throw ex`: Preserving Stack Trace

When you catch an exception in a `catch` block, you often need to re-throw it. The way you re-throw makes a crucial difference in how the exception's stack trace is handled.

### `throw;` (Rethrowing without modifying the stack trace)

  * **Syntax:** Just the `throw` keyword, without any exception object after it.
  * **Behavior:** This re-throws the *original* exception that was caught. Crucially, it **preserves the original stack trace** of the exception. The stack trace will show the exact line of code where the exception was originally thrown, as well as all subsequent method calls leading up to the `catch` block where it's being re-thrown.
  * **Purpose:** This is the **correct and recommended way to re-throw an exception** when you want to propagate it up the call stack while retaining all its original diagnostic information. You typically use this when you've performed some logging or specific cleanup in the `catch` block but cannot fully handle or recover from the exception at the current level.

### `throw ex;` (Rethrowing with a modified stack trace)

  * **Syntax:** The `throw` keyword followed by an exception variable (e.g., `ex`).
  * **Behavior:** This actually throws a *new* exception object, even if `ex` refers to the original exception object. When you do this, the stack trace is **reset to the point where `throw ex;` is executed**. The original stack trace information from where the exception first occurred is lost, or rather, it's truncated, making it appear as if the exception originated at the `throw ex;` line.
  * **Purpose:** This is generally considered an **anti-pattern** for rethrowing exceptions because it destroys crucial debugging information. It might be (mistakenly) used if you're trying to re-throw an exception obtained from another source, but even then, it's better to wrap it as an `InnerException`. The only time you'd explicitly `throw ex;` is if `ex` *is* a newly created exception object that you intend to throw for the first time or if you're deliberately wrapping it.

### How Rethrowing Affects Debugging and Error Logs

The impact of `throw;` versus `throw ex;` on debugging and error logs is significant:

  * **`throw;` (Preserves Context):**

      * **Debugging:** When you encounter the exception in a debugger, you can easily trace back through the entire call stack to the precise origin of the error.
      * **Error Logs:** Logging `ex.ToString()` (which is always recommended) will provide the complete, accurate stack trace, showing the full sequence of method calls leading to the exception. This is invaluable for pinpointing the root cause in production environments.

  * **`throw ex;` (Destroys Context):**

      * **Debugging:** The debugger will show the exception originating at the `throw ex;` line, making it much harder to understand the sequence of events that led to the actual problem. You lose visibility into the original context.
      * **Error Logs:** `ex.ToString()` will only show the stack trace from the `throw ex;` line downwards. The crucial information about *where the exception first happened* is missing, turning a solvable problem into a frustrating mystery.

### Code Examples:

```csharp
using System;
using System.IO;

public static class ThrowVsThrowEx
{
    public static void Run()
    {
        Console.WriteLine("--- throw; vs throw ex; ---");

        // Scenario 1: Demonstrating throw; (Correct way to rethrow)
        Console.WriteLine("\nScenario 1: Using throw; to preserve stack trace.");
        try
        {
            MethodA_ThrowsAndRethrows();
        }
        catch (Exception finalEx)
        {
            Console.WriteLine("[Main Catch]: Caught exception from MethodA:");
            Console.WriteLine(finalEx.ToString()); // This will show the full stack trace from MethodC
        }

        // Scenario 2: Demonstrating throw ex; (Incorrect way to rethrow)
        Console.WriteLine("\nScenario 2: Using throw ex; (WARNING: Destroys stack trace).");
        try
        {
            MethodB_ThrowsAndRethrowsBadly();
        }
        catch (Exception finalEx)
        {
            Console.WriteLine("[Main Catch]: Caught exception from MethodB:");
            Console.WriteLine(finalEx.ToString()); // This will show stack trace starting from MethodB_ThrowsAndRethrowsBadly
        }

        // Scenario 3: Throwing a new exception with InnerException (Good practice for wrapping)
        Console.WriteLine("\nScenario 3: Throwing new exception with InnerException (Good for wrapping).");
        try
        {
            MethodD_ThrowsAndWraps();
        }
        catch (Exception finalEx)
        {
            Console.WriteLine("[Main Catch]: Caught exception from MethodD:");
            Console.WriteLine(finalEx.ToString()); // This shows the new exception, but also its InnerException and its stack trace
        }

        Console.WriteLine();
    }

    // --- Scenario 1: Correct Rethrowing with throw; ---
    public static void MethodA_ThrowsAndRethrows()
    {
        Console.WriteLine("  [MethodA]: Calling MethodB_Internal.");
        try
        {
            MethodC_OriginalError(); // This is where the exception originates
        }
        catch (FileNotFoundException ex)
        {
            Console.WriteLine("  [MethodA Catch]: Caught FileNotFoundException. Logging and rethrowing.");
            // Log the exception details here if needed
            Console.WriteLine($"  [MethodA Log]: {ex.Message}");
            throw; // CORRECT: Re-throws the original 'ex' preserving its original stack trace
        }
    }

    public static void MethodC_OriginalError()
    {
        Console.WriteLine("    [MethodC]: Attempting file operation (will fail).");
        // Simulating the original error source
        File.ReadAllText("nonExistentFile.txt"); // This line is the true origin
    }

    // --- Scenario 2: Incorrect Rethrowing with throw ex; ---
    public static void MethodB_ThrowsAndRethrowsBadly()
    {
        Console.WriteLine("  [MethodB]: Calling MethodE_OriginalError.");
        try
        {
            MethodE_OriginalError(); // This is where the exception originates
        }
        catch (InvalidOperationException ex)
        {
            Console.WriteLine("  [MethodB Catch]: Caught InvalidOperationException. Logging and rethrowing BADLY.");
            // Log the exception details here if needed
            Console.WriteLine($"  [MethodB Log]: {ex.Message}");
            throw ex; // INCORRECT: Resets the stack trace to this line in MethodB
        }
    }

    public static void MethodE_OriginalError()
    {
        Console.WriteLine("    [MethodE]: Performing an invalid operation (will fail).");
        // Simulating the original error source
        throw new InvalidOperationException("This operation is not valid at this time."); // True origin
    }


    // --- Scenario 3: Good Practice: Wrapping an exception with InnerException ---
    public static void MethodD_ThrowsAndWraps()
    {
        Console.WriteLine("  [MethodD]: Calling MethodF_OriginalError.");
        try
        {
            MethodF_OriginalError(); // Original exception source
        }
        catch (FormatException ex)
        {
            Console.WriteLine("  [MethodD Catch]: Caught FormatException. Wrapping in custom exception.");
            // Log the original exception if needed
            Console.WriteLine($"  [MethodD Log]: Original error: {ex.Message}");

            // Create a new, more specific exception with the original as its InnerException
            throw new ApplicationException("Failed to process user input.", ex); // Good practice for wrapping
        }
    }

    public static void MethodF_OriginalError()
    {
        Console.WriteLine("    [MethodF]: Attempting to parse bad input (will fail).");
        int.Parse("not_a_number"); // Original exception source
    }
}
```

**Output Explanation:**

  * **Scenario 1 (`throw;`):** The output for `finalEx.ToString()` will clearly show `MethodC_OriginalError()` as the method where `FileNotFoundException` was originally thrown, followed by `MethodA_ThrowsAndRethrows()`, and then `Run()` (and `Main()`). The full lineage is preserved.
  * **Scenario 2 (`throw ex;`):** The output for `finalEx.ToString()` will show `MethodB_ThrowsAndRethrowsBadly()` as the method where `InvalidOperationException` was supposedly thrown, effectively hiding the `MethodE_OriginalError()` part of the stack trace. This makes it harder to debug, especially in complex call stacks.
  * **Scenario 3 (`throw new CustomException(..., ex);`):** The output will show `ApplicationException` as the top-level exception with its stack trace starting from `MethodD_ThrowsAndWraps()`. However, crucially, it will also include the details of the `InnerException` (`FormatException`) and *its* original stack trace (showing `MethodF_OriginalError()`). This is the best approach when you need to change the exception type but still provide full diagnostic context.

-----

### ðŸ§  Interview Angle: What's the correct way to rethrow an exception while preserving context?

**Answer:**

The correct way to rethrow an exception while preserving its full context (specifically, its original stack trace) is to use the `throw;` statement (just the `throw` keyword without any exception variable).

**Explanation:**

When an exception is caught in a `catch` block:

1.  **`throw;`**:

      * This tells the Common Language Runtime (CLR) to re-throw the *currently caught* exception.
      * The CLR internally uses a mechanism to prevent the modification of the stack trace. The `StackTrace` property of the `Exception` object will retain its original information, indicating the precise line of code where the exception was first thrown and the full sequence of method calls leading up to that point.
      * This is essential for debugging and accurate error logging, as it provides a clear picture of the exception's origin.

2.  **`throw ex;`**:

      * This creates a *new* exception instance, even though it's initialized with the values from the `ex` variable.
      * When this "new" exception is thrown, its stack trace is reset to the point where the `throw ex;` statement resides. The original stack information from the exception's true origin is overwritten and lost, making debugging significantly harder.

**When to use `throw;`:**

  * When you have performed some necessary logging or cleanup within the `catch` block.
  * When you cannot fully recover from the exception at the current level and need to propagate it up the call stack for a higher-level handler to deal with (e.g., a global error handler, or a calling method that is better equipped to handle the error).

**Alternative for changing exception type (preserving context):**

If you need to re-throw an exception but want to wrap it in a *different* exception type (e.g., a more domain-specific custom exception), you should pass the original exception as the `InnerException` to the new exception's constructor. This way, you provide a more meaningful exception type at the current layer, while still preserving the full original context for debugging via the `InnerException` property. This is a common and good practice in layered applications.