Let's clarify the crucial distinction between `throw;` and `throw ex;` in C\# exception handling.

### What is the difference between `throw;` and `throw ex;` in C\#?

The key difference between `throw;` and `throw ex;` lies in how they affect the **stack trace** of an exception when re-throwing it from within a `catch` block.

  * **`throw;` (Rethrow Original Exception)** ðŸš€

      * **Purpose:** This statement re-throws the *current* exception that was caught by the `catch` block. It indicates that you've handled some aspects of the exception (e.g., logged it, performed cleanup) but the current method cannot fully resolve it, and the exception needs to continue propagating up the call stack to a higher-level handler.
      * **Stack Trace Behavior:** Crucially, `throw;` **preserves the original stack trace**. The stack trace will show the full history of method calls from where the exception was *originally thrown* right up to the current re-throw point. This is vital for debugging as it tells you the complete execution path that led to the error.
      * **Analogy:** Imagine a parcel that was damaged at the first sorting office. When it reaches a second office, they examine it, try a minor repair, but realize they can't fully fix it. They then simply put the *same damaged parcel* back on the conveyor belt to the next office, along with all its original damage records.

  * **`throw ex;` (Throw New Exception Context)** ðŸ’¥

      * **Purpose:** This statement re-throws the `ex` object that was passed into the `catch` block. While it seems similar, it effectively treats `ex` as a *new* exception being thrown at the current line of code.
      * **Stack Trace Behavior:** When you use `throw ex;`, the stack trace is **reset** to the point where `throw ex;` is executed. The stack trace will effectively *start from the `throw ex;` line*, losing the original call stack information from where the exception first originated. This makes debugging significantly harder, as you lose crucial context about the error's source.
      * **Analogy:** Using the parcel analogy, the second sorting office examines the damaged parcel, but instead of putting the *original* damaged parcel back on the belt, they create a *brand new parcel* that just says "Parcel was damaged at the previous office." All the specific details about *where* and *how* it got damaged at the first office are lost in the new parcel's records.

-----

### When should you use `throw;` instead of `throw ex;`?

You should **almost always use `throw;` instead of `throw ex;`** when you intend to re-throw an exception from within a `catch` block.

The primary scenario for using `throw;` is when:

  * You want to perform some **intermediate handling or logging** of an exception.
  * You then realize that the current method **cannot fully recover** from the exception.
  * You need the exception to **continue propagating up the call stack** to a higher-level handler (e.g., a global error handler, or a calling method that is better equipped to deal with the error).
  * Crucially, you want to **preserve all the diagnostic information**, especially the original stack trace, for effective debugging and error analysis.

**Example:**

```csharp
public class DataService
{
    public void GetData()
    {
        try
        {
            // Simulate a database operation that might fail
            FetchDataFromDatabase();
        }
        catch (System.Data.SqlClient.SqlException ex)
        {
            // Log the exception for diagnostics
            Console.WriteLine($"[DataService] Database error occurred: {ex.Message}");

            // Re-throw the original exception to let a higher layer handle it (e.g., UI to show an error)
            // This preserves the full stack trace from FetchDataFromDatabase()
            throw; // CORRECT way to rethrow
        }
        catch (Exception ex)
        {
            Console.WriteLine($"[DataService] An unexpected error occurred: {ex.Message}");
            throw; // Rethrow any other unexpected exception
        }
    }

    private void FetchDataFromDatabase()
    {
        // This is where the actual error originates
        throw new System.Data.SqlClient.SqlException("Connection to DB failed.", new Exception("Inner DB Error"));
    }
}

public class Application
{
    public static void Main(string[] args)
    {
        DataService service = new DataService();
        try
        {
            service.GetData();
        }
        catch (Exception ex)
        {
            Console.WriteLine($"[Application] Caught final exception: {ex.Message}");
            Console.WriteLine("Full Stack Trace:");
            Console.WriteLine(ex.StackTrace); // This will show the trace all the way back to FetchDataFromDatabase()
        }
    }
}
```

The only time you might deliberately use `throw ex;` (or more commonly, `throw new SomeNewException("message", ex);`) is when:

  * You want to wrap the original exception in a **new, more specific exception type** that provides better context at the current layer (e.g., converting a `SqlException` into a `DataAccessException`). In this case, you should pass the original exception as the `InnerException` of the new exception to preserve the original stack trace and details.
      * `throw new DataAccessException("Failed to retrieve data.", ex);`
  * You explicitly want to **hide parts of the original stack trace** for security or simplification (though this is generally discouraged for debugging).

-----

### What happens to the stack trace when you use `throw ex;`?

When you use `throw ex;`, the **stack trace is reset**.

Specifically:

1.  The portion of the stack trace that indicates the origin of the `ex` exception is effectively **truncated or replaced**.
2.  The stack trace then begins from the line of code where `throw ex;` was executed.

This means that if you later inspect `ex.StackTrace`, you will see a stack trace that points *only* to the `throw ex;` line and the methods above it in the call stack, but it will **not** include the original sequence of method calls that led to the exception being thrown *initially*.

**Example to illustrate stack trace difference:**

```csharp
public class StackTraceDemo
{
    public void Level1()
    {
        Level2();
    }

    public void Level2()
    {
        try
        {
            Level3();
        }
        catch (NullReferenceException ex)
        {
            Console.WriteLine("\n--- Inside Level2 Catch Block ---");
            Console.WriteLine("Original Stack Trace from 'ex':");
            Console.WriteLine(ex.StackTrace); // This shows Level3 -> Level2

            Console.WriteLine("\n--- Re-throwing using throw ex; ---");
            // The stack trace will be reset to this line
            throw ex; // THIS RESETS THE STACK TRACE!
        }
    }

    public void Level3()
    {
        string s = null;
        Console.WriteLine("Attempting to cause NullReferenceException in Level3...");
        s.ToString(); // This throws NullReferenceException
    }
}

public class Program
{
    public static void Main(string[] args)
    {
        StackTraceDemo demo = new StackTraceDemo();
        try
        {
            demo.Level1();
        }
        catch (Exception ex)
        {
            Console.WriteLine("\n--- Caught in Main ---");
            Console.WriteLine("Final Stack Trace:");
            Console.WriteLine(ex.StackTrace);
        }
    }
}
```

**Expected Output (conceptual):**

```
Attempting to cause NullReferenceException in Level3...

--- Inside Level2 Catch Block ---
Original Stack Trace from 'ex':
   at StackTraceDemo.Level3() in ... (line where s.ToString() is)
   at StackTraceDemo.Level2() in ... (line where Level3() is called)
   ... (and so on up to the try block in Level2)

--- Re-throwing using throw ex; ---

--- Caught in Main ---
Final Stack Trace:
   at StackTraceDemo.Level2() in ... (line where throw ex; is)  // Stack trace STARTS HERE!
   at StackTraceDemo.Level1() in ... (line where Level2() is called)
   at Program.Main(String[] args) in ... (line where Level1() is called)
   ... (and so on)
```

Notice how `Level3()` is missing from the `Final Stack Trace` when `throw ex;` is used. This loss of information makes it very difficult to trace the actual origin of the bug. This is why `throw;` is the preferred mechanism for re-throwing exceptions.