Let's explore common scenarios involving exception rethrowing and how to handle them correctly to ensure robust logging, debugging, and telemetry.

-----

### ðŸ”¹ Your application logs donâ€™t show where the exception originated. On inspecting the code, you see `throw ex;`. What's the fix?

(Replace with `throw;` to preserve original stack trace.)

**The Issue:**

When you use `throw ex;` to rethrow an exception that you've caught, it effectively creates a *new* stack frame at the point of the `throw ex;` statement. This means the original part of the stack trace (the call stack leading up to where the exception *first* occurred) is lost or truncated. Your logs will only show the stack trace from the `throw ex;` line downwards, making it incredibly difficult to pinpoint the actual source of the problem.

**The Fix:**

Replace `throw ex;` with `throw;`.

The `throw;` statement (without an exception variable) tells the Common Language Runtime (CLR) to re-throw the *currently active* exception instance. This crucial difference ensures that the original stack trace is fully preserved, providing a complete and accurate picture of the exception's journey through your code.

**Code Example:**

```csharp
using System;
using System.IO;

public static class LoggingFix
{
    public static void Run()
    {
        Console.WriteLine("--- Logging Fix: throw ex; vs throw; ---");

        // Scenario 1: Demonstrating the problem with throw ex;
        Console.WriteLine("\nScenario 1: Logs show incorrect origin (due to throw ex;)");
        try
        {
            ProblematicMethodCall();
        }
        catch (Exception ex)
        {
            Console.WriteLine("[Main App Log]: Caught exception (ProblematicMethodCall):");
            Console.WriteLine(ex.ToString()); // Stack trace will start from ProblematicMethodCall
            Console.WriteLine("Notice how SourceOfError is missing from the stack trace.");
        }

        // Scenario 2: Demonstrating the fix with throw;
        Console.WriteLine("\nScenario 2: Logs show correct origin (using throw;)");
        try
        {
            FixedMethodCall();
        }
        catch (Exception ex)
        {
            Console.WriteLine("[Main App Log]: Caught exception (FixedMethodCall):");
            Console.WriteLine(ex.ToString()); // Stack trace will correctly show SourceOfError
            Console.WriteLine("Notice how SourceOfError is correctly present in the stack trace.");
        }

        Console.WriteLine();
    }

    public static void SourceOfError()
    {
        Console.WriteLine("  [SourceOfError]: Intentionally causing an error.");
        // This is the true origin of the exception
        throw new InvalidOperationException("Something went wrong at the core!");
    }

    public static void ProblematicMethodCall()
    {
        Console.WriteLine("  [ProblematicMethodCall]: Calling SourceOfError...");
        try
        {
            SourceOfError();
        }
        catch (InvalidOperationException ex)
        {
            Console.WriteLine("  [ProblematicMethodCall Catch]: Logging and rethrowing with throw ex;");
            // Log for local context (often here is where the problem lies)
            // Log.Error($"Error in ProblematicMethodCall: {ex.Message}");
            throw ex; // <-- This is the problematic line
        }
    }

    public static void FixedMethodCall()
    {
        Console.WriteLine("  [FixedMethodCall]: Calling SourceOfError...");
        try
        {
            SourceOfError();
        }
        catch (InvalidOperationException ex)
        {
            Console.WriteLine("  [FixedMethodCall Catch]: Logging and rethrowing with throw;");
            // Log for local context
            // Log.Error($"Error in FixedMethodCall: {ex.Message}");
            throw; // <-- This is the correct fix
        }
    }
}
```

-----

### ðŸ”¹ You're writing a wrapper around a third-party library. You catch a low-level exception, log it, and want to propagate it. What should you do?

(Use `throw;`, not `throw ex;`, to avoid losing original context unless you wrap it in a custom exception.)

**Approach:**

When wrapping a third-party library, you often want to translate its specific (and sometimes cryptic) exceptions into more meaningful, domain-specific exceptions for your application's consumers. However, it's crucial to retain the original low-level exception's details for debugging.

You have two primary good options here:

1.  **Direct Rethrowing with `throw;`:**

      * If the third-party exception is acceptable to expose to your consumers (or you just need to pass it up directly without changing its type), use `throw;`. This preserves the full original stack trace.
      * **Use when:** The upstream caller *can* (or *should*) understand and potentially handle the third-party exception type, and you just want to log it locally before propagating.

2.  **Wrapping in a Custom Exception with `InnerException` (Recommended):**

      * This is generally the preferred approach for library wrappers. You catch the low-level exception and throw a *new* custom exception (e.g., `ThirdPartyServiceUnavailableException`, `InvalidApiResponseException`).
      * Crucially, you pass the original low-level exception as the `innerException` argument to your custom exception's constructor. This preserves the entire exception chain and its stack traces.
      * **Use when:** You want to provide a cleaner, more abstract, and domain-relevant exception type to your consumers, while still enabling deep debugging by inspecting the `InnerException`.

**Code Example:**

```csharp
using System;
using System.Net.Http; // Simulating a third-party library exception

// Custom exception for our application
public class MyServiceIntegrationException : Exception
{
    public MyServiceIntegrationException(string message, Exception innerException = null)
        : base(message, innerException) { }
}

public static class ThirdPartyWrapper
{
    public static void Run()
    {
        Console.WriteLine("--- Wrapper Exception Handling ---");

        // Scenario 1: Propagate raw third-party exception (less common, but valid with throw;)
        Console.WriteLine("\nScenario 1: Propagating raw third-party exception.");
        try
        {
            CallThirdPartyService_RawPropagate();
        }
        catch (HttpRequestException ex)
        {
            Console.WriteLine("[Main App Catch]: Caught raw HttpRequestException:");
            Console.WriteLine(ex.ToString()); // Full stack trace including ThirdPartyLibrarySim
        }

        // Scenario 2: Wrap third-party exception in custom exception (recommended)
        Console.WriteLine("\nScenario 2: Wrapping third-party exception in custom exception.");
        try
        {
            CallThirdPartyService_Wrapped();
        }
        catch (MyServiceIntegrationException ex)
        {
            Console.WriteLine("[Main App Catch]: Caught MyServiceIntegrationException:");
            Console.WriteLine(ex.ToString()); // Shows MyServiceIntegrationException, then InnerException (HttpRequestException) and its stack
        }

        Console.WriteLine();
    }

    // Simulates a method in a third-party library
    private static void ThirdPartyLibrarySim()
    {
        Console.WriteLine("  [ThirdPartyLibrarySim]: Making an external call...");
        throw new HttpRequestException("HTTP 503 Service Unavailable");
    }

    // Option 1: Propagate raw exception (use throw;)
    public static void CallThirdPartyService_RawPropagate()
    {
        Console.WriteLine("  [Wrapper]: Calling third-party service (raw propagate).");
        try
        {
            ThirdPartyLibrarySim();
        }
        catch (HttpRequestException ex)
        {
            Console.WriteLine("  [Wrapper Catch]: Logging third-party exception locally.");
            // Log.Error($"Third-party error: {ex.ToString()}");
            throw; // Preserve original stack trace, propagate as HttpRequestException
        }
    }

    // Option 2: Wrap in custom exception (recommended)
    public static void CallThirdPartyService_Wrapped()
    {
        Console.WriteLine("  [Wrapper]: Calling third-party service (wrapped).");
        try
        {
            ThirdPartyLibrarySim();
        }
        catch (HttpRequestException ex)
        {
            Console.WriteLine("  [Wrapper Catch]: Logging and wrapping third-party exception.");
            // Log.Error($"Third-party error: {ex.ToString()}");
            // Create a new, domain-specific exception, passing the original as InnerException
            throw new MyServiceIntegrationException("Failed to integrate with third-party service.", ex);
        }
    }
}
```

-----

### ðŸ”¹ Have you ever faced a debugging issue due to incorrect rethrowing? How did you diagnose and fix it?

(Discuss missing stack trace, poor logs, code audit for `throw ex;`, fixed by changing to `throw;` or wrapping.)

**My Experience:**

Yes, absolutely. This is a classic "gotcha" in C\# that almost every developer encounters at some point. I've faced debugging issues due to `throw ex;` multiple times in my career, particularly in larger, more complex applications or microservices environments.

**How I Diagnosed It:**

The primary symptom was always the same: **missing or truncated stack traces in logs and monitoring tools.**

1.  **Logs Don't Point to the Source:** When an error occurred, the production logs (or even local dev logs) would show an exception, but its stack trace would only begin at a higher-level method, not the actual method where the underlying issue (e.g., a `NullReferenceException`, a specific database error) truly originated.
2.  **Ambiguous Error Messages:** Without the full stack, it was hard to tell if it was a data issue, a configuration problem, or a fundamental code bug. The `ex.Message` might be generic, and without the context, it was like finding a needle in a haystack.
3.  **Local Reproduction Difficulties:** Sometimes, the issue was hard to reproduce locally because the truncated stack trace didn't give enough clues to set up the exact failing scenario.

**How I Fixed It:**

The diagnosis almost always led to a **code audit** focusing on exception handling patterns:

1.  **Search for `throw ex;`:** I'd perform a codebase search for ` throw  ` followed by a variable name (especially `throw ex;`).

2.  **Analyze Context:** For each `throw ex;` instance, I'd analyze the `catch` block's intent:

      * Was it just logging and rethrowing? If so, it should be `throw;`.
      * Was it catching a low-level exception to transform it into a higher-level, domain-specific exception? If so, it should use `throw new CustomException("message", ex);` to preserve the original as an `InnerException`.
      * Was it intended to be a *new* exception entirely? (This is rare for `throw ex;` but possible if `ex` was actually a *newly created* exception instance, which would be syntactically `throw new Exception("...", ex);` anyway).

3.  **Implement Fixes:**

      * **Changed `throw ex;` to `throw;`**: This was the most common fix.
      * **Refactored to wrap with `InnerException`**: For wrapper layers or domain boundaries where a new exception type was genuinely needed.
      * **Ensured `ex.ToString()` was used for logging**: Verified that logging calls always captured the full `ToString()` output of the exception object, not just `ex.Message`.

This pattern of diagnose-search-fix became standard practice for debugging elusive issues related to exception context loss.

-----

### ðŸ”¹ In a shared method, you catch exceptions for logging. Your team wants to preserve original source info for telemetry. What's your approach?

(Log details inside catch, then `throw;`. If wrapping, use `new CustomException("msg", ex)` to nest.)

**Approach:**

This is a very common and important requirement in production systems. The goal is to provide granular logging for local context/diagnostics while ensuring the ultimate telemetry system receives the full, accurate stack trace from the origin.

1.  **Log Locally with Full Details:**

      * Inside the `catch` block, immediately log the caught exception using `ex.ToString()`. This captures all details (type, message, stack trace, inner exception) at the point it's handled. This log can be used for local troubleshooting, debugging, or specific alerts for that method.
      * Include any relevant contextual data (e.g., input parameters, user ID, correlation ID) in the log message.

2.  **Preserve and Propagate the Original Exception:**

      * **Option A: Simple Rethrow (`throw;`)**: If the shared method doesn't need to change the exception type for its callers, simply re-throw the original exception using `throw;`. This ensures the upstream caller (and thus the telemetry system) receives the exception with its completely intact original stack trace. This is the simplest and often most appropriate solution.

        ```csharp
        public void SharedMethodA(string input)
        {
            try
            {
                // Core logic that might throw
                SomeInternalOperation(input);
            }
            catch (ArgumentException ex) // Catch specific, expected exceptions
            {
                // 1. Log locally with full details and context
                Logger.Warn($"[SharedMethodA]: Invalid argument for input '{input}'. Exception: {ex.ToString()}");
                // 2. Re-throw to preserve original context for telemetry/upstream
                throw;
            }
            catch (Exception ex) // Catch any unexpected exceptions
            {
                Logger.Error($"[SharedMethodA]: Unexpected error processing input '{input}'. Exception: {ex.ToString()}");
                throw; // Preserve for telemetry
            }
        }
        ```

      * **Option B: Wrap in Custom Exception (`throw new CustomException("msg", ex);`)**: If the shared method acts as a boundary (e.g., between a lower-level library and business logic, or different microservices), and you want to present a more abstract or domain-specific exception type to its consumers, wrap the original exception.

        ```csharp
        // Define a custom exception for this service/layer
        public class MyServiceException : Exception
        {
            public MyServiceException(string message, Exception innerException = null)
                : base(message, innerException) { }
        }

        public void SharedMethodB(string userId)
        {
            try
            {
                // Interaction with a low-level data access layer or external API
                DataAccessLayer.GetDataForUser(userId);
            }
            catch (SqlException ex) // Catch low-level exception
            {
                // 1. Log locally (for DBA/infra teams)
                Logger.Error($"[SharedMethodB]: Database error for user {userId}. Exception: {ex.ToString()}");
                // 2. Wrap and throw a higher-level exception for application consumers
                throw new MyServiceException($"Failed to retrieve user data for {userId}.", ex);
            }
            catch (Exception ex) // General unexpected errors
            {
                Logger.Fatal($"[SharedMethodB]: Critical unhandled error for user {userId}. Exception: {ex.ToString()}");
                throw new MyServiceException($"An unexpected critical error occurred.", ex);
            }
        }
        ```

In both cases, when the exception eventually reaches a global telemetry handler (e.g., Application Insights, Sentry, ELK stack), it can inspect the `Exception` object (and its `InnerException` if applicable) to extract the complete stack trace and all relevant details, ensuring accurate error reporting and analysis.

-----

### ðŸ”¹ You rethrow an exception from a `catch` block inside a custom service. Later, the logs show only internal helper methods in the stack trace. What's wrong?

(`throw ex;` was used â€” replaced with `throw;` to retain upstream method calls.)

**What's Wrong:**

This is the classic symptom of using `throw ex;` instead of `throw;`.

When the exception was rethrown from the `catch` block in your custom service:

  * If `throw ex;` was used, the stack trace was reset to the line where `throw ex;` was called. All the upstream methods (the actual public API calls, the controller action, the business logic methods) that invoked your custom service and led to the original exception were effectively removed from the stack trace in the logs.
  * The logs only show the execution path *within* your custom service and its internal helper methods, not the full context of how your service was called from the broader application.

**The Fix:**

The solution is to replace all instances of `throw ex;` with `throw;` in your custom service's `catch` blocks where the intention is to propagate the original exception.

**Code Example (Revisiting `ProblematicMethodCall` from above):**

Imagine `ProblematicMethodCall` is your custom service method.

```csharp
// Original problematic code in your custom service
public class MyCustomService
{
    public void ServiceOperation()
    {
        try
        {
            // Somewhere deep inside your service, an error occurs
            HelperMethodThatFails();
        }
        catch (InvalidOperationException ex)
        {
            // Log for local diagnostics
            // Logger.Error($"Error in MyCustomService.ServiceOperation: {ex.Message}");
            throw ex; // <-- Problematic! This line becomes the "origin" in the stack trace
        }
    }

    private void HelperMethodThatFails()
    {
        // This is the actual source
        throw new InvalidOperationException("Helper logic failed.");
    }
}

// In your application logs, you'd see:
// MyCustomService.ServiceOperation() at line X (where throw ex; is)
// ... then MyController.Action()
// ... then Main()
// The HelperMethodThatFails() part would be missing from the stack trace.

// The Fix:
public class MyCustomServiceFixed
{
    public void ServiceOperation()
    {
        try
        {
            HelperMethodThatFails();
        }
        catch (InvalidOperationException ex)
        {
            // Logger.Error($"Error in MyCustomService.ServiceOperation: {ex.Message}");
            throw; // <-- Correct! Preserves HelperMethodThatFails() in the stack trace
        }
    }

    private void HelperMethodThatFails()
    {
        throw new InvalidOperationException("Helper logic failed.");
    }
}
```

-----

### ðŸ”¹ How would you rethrow an exception with additional context but still preserve the original exception details?

(Use: `throw new CustomException("msg", ex);` â€” sets `InnerException` and keeps full chain.)

**Approach:**

This is done by creating a *new* exception instance (often a custom exception specific to your application's domain) and passing the original exception object into the new exception's constructor as the `innerException` argument.

The `InnerException` property of an `Exception` object is specifically designed for this purpose: to chain exceptions together. When you call `ToString()` on the outer exception, it will recursively include the details (type, message, stack trace) of its `InnerException` and any subsequent `InnerExceptions` in the chain.

**Code Example:**

```csharp
using System;
using System.IO;

// Define a custom exception for our application domain
public class DataProcessingException : Exception
{
    public string ContextualData { get; }

    public DataProcessingException(string message, string contextualData, Exception innerException = null)
        : base(message, innerException)
    {
        ContextualData = contextualData;
    }

    // Override ToString to include custom data in log output
    public override string ToString()
    {
        return $"{base.ToString()}\nContextual Data: {ContextualData}";
    }
}

public static class RethrowWithContext
{
    public static void Run()
    {
        Console.WriteLine("--- Rethrowing with Additional Context ---");
        try
        {
            ProcessDataFromFile("example.txt", "user_123");
        }
        catch (DataProcessingException ex)
        {
            Console.WriteLine("[Main App Catch]: Caught DataProcessingException:");
            Console.WriteLine(ex.ToString()); // Will show DataProcessingException, then InnerException (FileNotFoundException), and their respective stack traces.
        }
        Console.WriteLine();
    }

    public static void ReadFileContent(string filename)
    {
        Console.WriteLine($"  [ReadFileContent]: Attempting to read '{filename}'.");
        // This is the original source of the low-level exception
        File.ReadAllText(filename); // Will throw FileNotFoundException
    }

    public static void ProcessDataFromFile(string filename, string userId)
    {
        Console.WriteLine($"  [ProcessDataFromFile]: Processing data for user '{userId}' from '{filename}'.");
        try
        {
            ReadFileContent(filename);
            // Simulate more processing
        }
        catch (FileNotFoundException ex)
        {
            Console.WriteLine("  [ProcessDataFromFile Catch]: Caught low-level FileNotFoundException.");
            // Log the low-level exception locally if needed
            // Logger.Warn($"File not found for user {userId}: {ex.Message}");

            // Create a new, domain-specific exception, adding contextual data
            // and linking the original exception as the InnerException.
            throw new DataProcessingException(
                $"Failed to process data from file '{filename}' for user '{userId}'.",
                $"Filename: {filename}, UserID: {userId}",
                ex // Pass the original exception as InnerException
            );
        }
        catch (Exception ex)
        {
            // Catch any other unexpected exceptions and wrap them too
            throw new DataProcessingException(
                $"An unexpected error occurred during data processing for user '{userId}' from '{filename}'.",
                $"Filename: {filename}, UserID: {userId}",
                ex // Always pass the original exception
            );
        }
    }
}
```

-----

### ðŸ”¹ When rethrowing inside a Polly retry policy or middleware pipeline, what care should you take with `throw`?

(Always use `throw;` to ensure upstream layers (retry, logging, metrics) get the real origin â€” helps observability.)

**Care with `throw` in Polly/Middleware:**

In a pipeline or policy chain (like Polly for retries, or ASP.NET Core middleware), each component might have a `try-catch` block. When an exception is caught in one layer and needs to be passed to the next (e.g., the retry policy, or the next middleware in the chain, or finally to the global error handler), it's absolutely crucial to **always use `throw;`**.

**Why `throw;` is critical here:**

1.  **Preserving Original Context for Policies:** Polly policies often need to inspect the *original* exception type and its stack trace to determine if an operation should be retried or handled. If `throw ex;` were used, the policy might receive a truncated stack trace or an exception that appears to originate from an intermediate layer, making it impossible to correctly identify the transient nature of the fault.
2.  **Accurate Telemetry and Logging:** Middleware pipelines often culminate in a global error handling middleware or logging sink (e.g., Application Insights, Sentry). If any layer in the pipeline uses `throw ex;`, the telemetry system will receive a corrupted stack trace, significantly hindering debugging and root cause analysis in production. You won't know the true origin of the error.
3.  **Observability:** For effective monitoring and alerting, it's vital that the reported exceptions contain complete and accurate information about *where* and *how* the error truly occurred. `throw;` ensures this observability.

**Code Example (Conceptual):**

```csharp
using System;
using System.Net.Http;
using System.Threading.Tasks;
using Polly; // For retry policies

public static class PipelineRethrow
{
    public static async Task Run()
    {
        Console.WriteLine("--- Rethrowing in Pipeline/Policy ---");

        var resiliencePolicy = Policy
            .Handle<HttpRequestException>() // Policy handles HttpRequestException
            .WaitAndRetryAsync(3, _ => TimeSpan.FromSeconds(1));

        try
        {
            await resiliencePolicy.ExecuteAsync(async () =>
            {
                await NetworkLayer.MakeApiCall(); // This will throw HttpRequestException
                return true;
            });
            Console.WriteLine("[Main]: API call succeeded after retries.");
        }
        catch (Exception ex)
        {
            Console.WriteLine("[Main Catch]: Final exception caught:");
            Console.WriteLine(ex.ToString()); // This will correctly show original stack including DataAccessLayer.SimulateApiCallFailure
        }
        Console.WriteLine();
    }
}

// Simulating a low-level network or data access layer
public class DataAccessLayer
{
    private static int _attemptCount = 0;

    public static async Task SimulateApiCallFailure()
    {
        Console.WriteLine($"  [DataAccessLayer]: Attempting API call (attempt {_attemptCount + 1}).");
        _attemptCount++;
        if (_attemptCount <= 2) // Fail for first 2 calls to trigger retry
        {
            Console.WriteLine("    [DataAccessLayer]: Simulating network error.");
            throw new HttpRequestException("Simulated network connectivity issue.");
        }
        Console.WriteLine("    [DataAccessLayer]: API call succeeded.");
        await Task.Delay(10); // Simulate some work
    }
}

// Simulating an intermediate "NetworkLayer" in a pipeline (e.g., HTTP client wrapper, middleware)
public class NetworkLayer
{
    public static async Task MakeApiCall()
    {
        Console.WriteLine("  [NetworkLayer]: Preparing API call.");
        try
        {
            await DataAccessLayer.SimulateApiCallFailure();
        }
        catch (HttpRequestException ex)
        {
            Console.WriteLine("    [NetworkLayer Catch]: Caught HttpRequestException from DataAccessLayer. Logging locally and rethrowing.");
            // Logger.Error($"Network call failed: {ex.Message}");
            throw; // CRITICAL: Use throw; to preserve original stack trace for Polly/upstream
        }
    }
}
```

In this example, if `NetworkLayer` used `throw ex;`, the Polly policy (and subsequently the `Main` method's `catch`) would see the `HttpRequestException` as originating from `NetworkLayer.MakeApiCall`, hiding the fact that `DataAccessLayer.SimulateApiCallFailure` was the original source. By using `throw;`, the full chain is preserved, making diagnosis much easier.